Workbook

Sheet Gamma Data
A1: STRIKE | B1: CALL GAMMA | C1: PUT GAMMA
A2: 4095 | B2: 0 | C2: 0
A3: 4100 | B3: 0 | C3: 14
A4: 4105 | B4: 0 | C4: 1
A5: 4110 | B5: 0 | C5: 1
A6: 4115 | B6: 0 | C6: 1
A7: 4120 | B7: 0 | C7: 2
A8: 4125 | B8: 0 | C8: 6
A9: 4130 | B9: 0 | C9: 15
A10: 4135 | B10: 0 | C10: 3
A11: 4140 | B11: 1 | C11: 2
A12: 4145 | B12: 0 | C12: 8
A13: 4150 | B13: 1 | C13: 18
... A109: 4650 | B109: 0 | C109: 0

Sheet GEX Calc
A1: STRIKE | B1: NET GAMMA | C1: GROSS GAMMA | D1: ประเภท (เกณฑ์ 1.5×) | E1: ความแรง | F1: โซน | I1: ข้อมูลวันที่ / สัญญา | J1: 2026-10-06 G1WV6 (Week 1 - OCT 2026) | AB1: Pin score (ตัวช่วย)
A2: =IF('Gamma Data'!A2="","",'Gamma Data'!A2) | B2: =IF(A2="","",'Gamma Data'!B2-'Gamma Data'!C2) | C2: =IF(A2="","",ABS('Gamma Data'!B2)+ABS('Gamma Data'!C2)) | D2: =IF(A2="","",IF(C2=0,"-",IF(AND('Gamma Data'!B2>0,'Gamma Data'!B2>='Gamma Data'!C2*1.5),"Call Wall",IF(AND('Gamma Data'!C2>0,'Gamma Data'!C2>='Gamma Data'!B2*1.5),"Put Wall","(mixed)")))) | E2: =IF(OR(A2="",$J$12=0),"",C2/$J$12) | F2: =IF(A2="","",IF(C2>=2*$J$12,"จุดหนืด",IF(C2<=0.5*$J$12,"air pocket",""))) | H2: =IF(AND(A2>=$J$6,'Gamma Data'!B2>0,'Gamma Data'!B2>='Gamma Data'!C2*1.5),'Gamma Data'!B2,0) | I2: รวม Call Gamma | J2: =SUM('Gamma Data'!$B$2:$B$152) | AB2: =IF(NOT(ISNUMBER('Gamma Data'!A2)),"",IF((ABS('Gamma Data'!B2)+ABS('Gamma Data'!C2))=0,"",IF(OR(ABS('Gamma Data'!A2-$J$6)>$J$6*$J$26,ABS('Gamma Data'!A2-$J$6)<$J$28),"",(ABS('Gamma Data'!B2)+ABS('Gamma Data'!C2))/MAX(ABS('Gamma Data'!A2-$J$6)/($J$6*0.005),1)+ROW()/1000000000)))
A3: =IF('Gamma Data'!A3="","",'Gamma Data'!A3) | B3: =IF(A3="","",'Gamma Data'!B3-'Gamma Data'!C3) | C3: =IF(A3="","",ABS('Gamma Data'!B3)+ABS('Gamma Data'!C3)) | D3: =IF(A3="","",IF(C3=0,"-",IF(AND('Gamma Data'!B3>0,'Gamma Data'!B3>='Gamma Data'!C3*1.5),"Call Wall",IF(AND('Gamma Data'!C3>0,'Gamma Data'!C3>='Gamma Data'!B3*1.5),"Put Wall","(mixed)")))) | E3: =IF(OR(A3="",$J$12=0),"",C3/$J$12) | F3: =IF(A3="","",IF(C3>=2*$J$12,"จุดหนืด",IF(C3<=0.5*$J$12,"air pocket",""))) | H3: =IF(AND(A3>=$J$6,'Gamma Data'!B3>0,'Gamma Data'!B3>='Gamma Data'!C3*1.5),'Gamma Data'!B3,0) | I3: รวม Put Gamma | J3: =SUM('Gamma Data'!$C$2:$C$152) | AB3: =IF(NOT(ISNUMBER('Gamma Data'!A3)),"",IF((ABS('Gamma Data'!B3)+ABS('Gamma Data'!C3))=0,"",IF(OR(ABS('Gamma Data'!A3-$J$6)>$J$6*$J$26,ABS('Gamma Data'!A3-$J$6)<$J$28),"",(ABS('Gamma Data'!B3)+ABS('Gamma Data'!C3))/MAX(ABS('Gamma Data'!A3-$J$6)/($J$6*0.005),1)+ROW()/1000000000)))
A4: =IF('Gamma Data'!A4="","",'Gamma Data'!A4) | B4: =IF(A4="","",'Gamma Data'!B4-'Gamma Data'!C4) | C4: =IF(A4="","",ABS('Gamma Data'!B4)+ABS('Gamma Data'!C4)) | D4: =IF(A4="","",IF(C4=0,"-",IF(AND('Gamma Data'!B4>0,'Gamma Data'!B4>='Gamma Data'!C4*1.5),"Call Wall",IF(AND('Gamma Data'!C4>0,'Gamma Data'!C4>='Gamma Data'!B4*1.5),"Put Wall","(mixed)")))) | E4: =IF(OR(A4="",$J$12=0),"",C4/$J$12) | F4: =IF(A4="","",IF(C4>=2*$J$12,"จุดหนืด",IF(C4<=0.5*$J$12,"air pocket",""))) | H4: =IF(AND(A4>=$J$6,'Gamma Data'!B4>0,'Gamma Data'!B4>='Gamma Data'!C4*1.5),'Gamma Data'!B4,0) | I4: NET GEX | J4: =J2-J3 | AB4: =IF(NOT(ISNUMBER('Gamma Data'!A4)),"",IF((ABS('Gamma Data'!B4)+ABS('Gamma Data'!C4))=0,"",IF(OR(ABS('Gamma Data'!A4-$J$6)>$J$6*$J$26,ABS('Gamma Data'!A4-$J$6)<$J$28),"",(ABS('Gamma Data'!B4)+ABS('Gamma Data'!C4))/MAX(ABS('Gamma Data'!A4-$J$6)/($J$6*0.005),1)+ROW()/1000000000)))
A5: =IF('Gamma Data'!A5="","",'Gamma Data'!A5) | B5: =IF(A5="","",'Gamma Data'!B5-'Gamma Data'!C5) | C5: =IF(A5="","",ABS('Gamma Data'!B5)+ABS('Gamma Data'!C5)) | D5: =IF(A5="","",IF(C5=0,"-",IF(AND('Gamma Data'!B5>0,'Gamma Data'!B5>='Gamma Data'!C5*1.5),"Call Wall",IF(AND('Gamma Data'!C5>0,'Gamma Data'!C5>='Gamma Data'!B5*1.5),"Put Wall","(mixed)")))) | E5: =IF(OR(A5="",$J$12=0),"",C5/$J$12) | F5: =IF(A5="","",IF(C5>=2*$J$12,"จุดหนืด",IF(C5<=0.5*$J$12,"air pocket",""))) | H5: =IF(AND(A5>=$J$6,'Gamma Data'!B5>0,'Gamma Data'!B5>='Gamma Data'!C5*1.5),'Gamma Data'!B5,0) | I5: สถานะ | J5: =IF(J18="","",IF(J18<0.05,"ไม่มีโหมด",IF(J4>0,"Positive GEX (นิ่ง)","Negative GEX (วิ่ง)"))) | AB5: =IF(NOT(ISNUMBER('Gamma Data'!A5)),"",IF((ABS('Gamma Data'!B5)+ABS('Gamma Data'!C5))=0,"",IF(OR(ABS('Gamma Data'!A5-$J$6)>$J$6*$J$26,ABS('Gamma Data'!A5-$J$6)<$J$28),"",(ABS('Gamma Data'!B5)+ABS('Gamma Data'!C5))/MAX(ABS('Gamma Data'!A5-$J$6)/($J$6*0.005),1)+ROW()/1000000000)))
A6: =IF('Gamma Data'!A6="","",'Gamma Data'!A6) | B6: =IF(A6="","",'Gamma Data'!B6-'Gamma Data'!C6) | C6: =IF(A6="","",ABS('Gamma Data'!B6)+ABS('Gamma Data'!C6)) | D6: =IF(A6="","",IF(C6=0,"-",IF(AND('Gamma Data'!B6>0,'Gamma Data'!B6>='Gamma Data'!C6*1.5),"Call Wall",IF(AND('Gamma Data'!C6>0,'Gamma Data'!C6>='Gamma Data'!B6*1.5),"Put Wall","(mixed)")))) | E6: =IF(OR(A6="",$J$12=0),"",C6/$J$12) | F6: =IF(A6="","",IF(C6>=2*$J$12,"จุดหนืด",IF(C6<=0.5*$J$12,"air pocket",""))) | H6: =IF(AND(A6>=$J$6,'Gamma Data'!B6>0,'Gamma Data'!B6>='Gamma Data'!C6*1.5),'Gamma Data'!B6,0) | I6: ราคาปัจจุบัน (กรอกเอง) | J6: 4158.9 | AB6: =IF(NOT(ISNUMBER('Gamma Data'!A6)),"",IF((ABS('Gamma Data'!B6)+ABS('Gamma Data'!C6))=0,"",IF(OR(ABS('Gamma Data'!A6-$J$6)>$J$6*$J$26,ABS('Gamma Data'!A6-$J$6)<$J$28),"",(ABS('Gamma Data'!B6)+ABS('Gamma Data'!C6))/MAX(ABS('Gamma Data'!A6-$J$6)/($J$6*0.005),1)+ROW()/1000000000)))
A7: =IF('Gamma Data'!A7="","",'Gamma Data'!A7) | B7: =IF(A7="","",'Gamma Data'!B7-'Gamma Data'!C7) | C7: =IF(A7="","",ABS('Gamma Data'!B7)+ABS('Gamma Data'!C7)) | D7: =IF(A7="","",IF(C7=0,"-",IF(AND('Gamma Data'!B7>0,'Gamma Data'!B7>='Gamma Data'!C7*1.5),"Call Wall",IF(AND('Gamma Data'!C7>0,'Gamma Data'!C7>='Gamma Data'!B7*1.5),"Put Wall","(mixed)")))) | E7: =IF(OR(A7="",$J$12=0),"",C7/$J$12) | F7: =IF(A7="","",IF(C7>=2*$J$12,"จุดหนืด",IF(C7<=0.5*$J$12,"air pocket",""))) | H7: =IF(AND(A7>=$J$6,'Gamma Data'!B7>0,'Gamma Data'!B7>='Gamma Data'!C7*1.5),'Gamma Data'!B7,0) | I7: =IF(AND(A7<=$J$6,'Gamma Data'!C7>0,'Gamma Data'!C7>='Gamma Data'!B7*1.5),'Gamma Data'!C7,0) | AB7: =IF(NOT(ISNUMBER('Gamma Data'!A7)),"",IF((ABS('Gamma Data'!B7)+ABS('Gamma Data'!C7))=0,"",IF(OR(ABS('Gamma Data'!A7-$J$6)>$J$6*$J$26,ABS('Gamma Data'!A7-$J$6)<$J$28),"",(ABS('Gamma Data'!B7)+ABS('Gamma Data'!C7))/MAX(ABS('Gamma Data'!A7-$J$6)/($J$6*0.005),1)+ROW()/1000000000)))
A8: =IF('Gamma Data'!A8="","",'Gamma Data'!A8) | B8: =IF(A8="","",'Gamma Data'!B8-'Gamma Data'!C8) | C8: =IF(A8="","",ABS('Gamma Data'!B8)+ABS('Gamma Data'!C8)) | D8: =IF(A8="","",IF(C8=0,"-",IF(AND('Gamma Data'!B8>0,'Gamma Data'!B8>='Gamma Data'!C8*1.5),"Call Wall",IF(AND('Gamma Data'!C8>0,'Gamma Data'!C8>='Gamma Data'!B8*1.5),"Put Wall","(mixed)")))) | E8: =IF(OR(A8="",$J$12=0),"",C8/$J$12) | F8: =IF(A8="","",IF(C8>=2*$J$12,"จุดหนืด",IF(C8<=0.5*$J$12,"air pocket",""))) | H8: =IF(AND(A8>=$J$6,'Gamma Data'!B8>0,'Gamma Data'!B8>='Gamma Data'!C8*1.5),'Gamma Data'!B8,0) | I8: ── ระดับสำคัญ (เกณฑ์ 1.5×) ── | AB8: =IF(NOT(ISNUMBER('Gamma Data'!A8)),"",IF((ABS('Gamma Data'!B8)+ABS('Gamma Data'!C8))=0,"",IF(OR(ABS('Gamma Data'!A8-$J$6)>$J$6*$J$26,ABS('Gamma Data'!A8-$J$6)<$J$28),"",(ABS('Gamma Data'!B8)+ABS('Gamma Data'!C8))/MAX(ABS('Gamma Data'!A8-$J$6)/($J$6*0.005),1)+ROW()/1000000000)))
A9: =IF('Gamma Data'!A9="","",'Gamma Data'!A9) | B9: =IF(A9="","",'Gamma Data'!B9-'Gamma Data'!C9) | C9: =IF(A9="","",ABS('Gamma Data'!B9)+ABS('Gamma Data'!C9)) | D9: =IF(A9="","",IF(C9=0,"-",IF(AND('Gamma Data'!B9>0,'Gamma Data'!B9>='Gamma Data'!C9*1.5),"Call Wall",IF(AND('Gamma Data'!C9>0,'Gamma Data'!C9>='Gamma Data'!B9*1.5),"Put Wall","(mixed)")))) | E9: =IF(OR(A9="",$J$12=0),"",C9/$J$12) | F9: =IF(A9="","",IF(C9>=2*$J$12,"จุดหนืด",IF(C9<=0.5*$J$12,"air pocket",""))) | H9: =IF(AND(A9>=$J$6,'Gamma Data'!B9>0,'Gamma Data'!B9>='Gamma Data'!C9*1.5),'Gamma Data'!B9,0) | I9: Call Wall | J9: {=IFERROR(INDEX('Gamma Data'!$A$2:$A$152,MATCH(MAX(IF(('Gamma Data'!$A$2:$A$152>=$J$6)*('Gamma Data'!$B$2:$B$152>0)*('Gamma Data'!$B$2:$B$152>='Gamma Data'!$C$2:$C$152*1.5),'Gamma Data'!$B$2:$B$152)),IF(('Gamma Data'!$A$2:$A$152>=$J$6)*('Gamma Data'!$B$2:$B$152>0)*('Gamma Data'!$B$2:$B$152>='Gamma Data'!$C$2:$C$152*1.5),'Gamma Data'!$B$2:$B$152),0)),"ไม่มี strike ที่ผ่านเกณฑ์")} | AB9: =IF(NOT(ISNUMBER('Gamma Data'!A9)),"",IF((ABS('Gamma Data'!B9)+ABS('Gamma Data'!C9))=0,"",IF(OR(ABS('Gamma Data'!A9-$J$6)>$J$6*$J$26,ABS('Gamma Data'!A9-$J$6)<$J$28),"",(ABS('Gamma Data'!B9)+ABS('Gamma Data'!C9))/MAX(ABS('Gamma Data'!A9-$J$6)/($J$6*0.005),1)+ROW()/1000000000)))
A10: =IF('Gamma Data'!A10="","",'Gamma Data'!A10) | B10: =IF(A10="","",'Gamma Data'!B10-'Gamma Data'!C10) | C10: =IF(A10="","",ABS('Gamma Data'!B10)+ABS('Gamma Data'!C10)) | D10: =IF(A10="","",IF(C10=0,"-",IF(AND('Gamma Data'!B10>0,'Gamma Data'!B10>='Gamma Data'!C10*1.5),"Call Wall",IF(AND('Gamma Data'!C10>0,'Gamma Data'!C10>='Gamma Data'!B10*1.5),"Put Wall","(mixed)")))) | E10: =IF(OR(A10="",$J$12=0),"",C10/$J$12) | F10: =IF(A10="","",IF(C10>=2*$J$12,"จุดหนืด",IF(C10<=0.5*$J$12,"air pocket",""))) | H10: =IF(AND(A10>=$J$6,'Gamma Data'!B10>0,'Gamma Data'!B10>='Gamma Data'!C10*1.5),'Gamma Data'!B10,0) | I10: Put Wall | J10: {=IFERROR(INDEX('Gamma Data'!$A$2:$A$152,MATCH(MAX(IF(('Gamma Data'!$A$2:$A$152<=$J$6)*('Gamma Data'!$C$2:$C$152>0)*('Gamma Data'!$C$2:$C$152>='Gamma Data'!$B$2:$B$152*1.5),'Gamma Data'!$C$2:$C$152)),IF(('Gamma Data'!$A$2:$A$152<=$J$6)*('Gamma Data'!$C$2:$C$152>0)*('Gamma Data'!$C$2:$C$152>='Gamma Data'!$B$2:$B$152*1.5),'Gamma Data'!$C$2:$C$152),0)),"ไม่มี strike ที่ผ่านเกณฑ์")} | AB10: =IF(NOT(ISNUMBER('Gamma Data'!A10)),"",IF((ABS('Gamma Data'!B10)+ABS('Gamma Data'!C10))=0,"",IF(OR(ABS('Gamma Data'!A10-$J$6)>$J$6*$J$26,ABS('Gamma Data'!A10-$J$6)<$J$28),"",(ABS('Gamma Data'!B10)+ABS('Gamma Data'!C10))/MAX(ABS('Gamma Data'!A10-$J$6)/($J$6*0.005),1)+ROW()/1000000000)))
A11: =IF('Gamma Data'!A11="","",'Gamma Data'!A11) | B11: =IF(A11="","",'Gamma Data'!B11-'Gamma Data'!C11) | C11: =IF(A11="","",ABS('Gamma Data'!B11)+ABS('Gamma Data'!C11)) | D11: =IF(A11="","",IF(C11=0,"-",IF(AND('Gamma Data'!B11>0,'Gamma Data'!B11>='Gamma Data'!C11*1.5),"Call Wall",IF(AND('Gamma Data'!C11>0,'Gamma Data'!C11>='Gamma Data'!B11*1.5),"Put Wall","(mixed)")))) | E11: =IF(OR(A11="",$J$12=0),"",C11/$J$12) | F11: =IF(A11="","",IF(C11>=2*$J$12,"จุดหนืด",IF(C11<=0.5*$J$12,"air pocket",""))) | H11: =IF(AND(A11>=$J$6,'Gamma Data'!B11>0,'Gamma Data'!B11>='Gamma Data'!C11*1.5),'Gamma Data'!B11,0) | I11: Gross สูงสุด (จุดหนืดที่สุด) | J11: {=INDEX('Gamma Data'!$A$2:$A$152,MATCH(MAX(ABS('Gamma Data'!$B$2:$B$152)+ABS('Gamma Data'!$C$2:$C$152)),ABS('Gamma Data'!$B$2:$B$152)+ABS('Gamma Data'!$C$2:$C$152),0))} | AB11: =IF(NOT(ISNUMBER('Gamma Data'!A11)),"",IF((ABS('Gamma Data'!B11)+ABS('Gamma Data'!C11))=0,"",IF(OR(ABS('Gamma Data'!A11-$J$6)>$J$6*$J$26,ABS('Gamma Data'!A11-$J$6)<$J$28),"",(ABS('Gamma Data'!B11)+ABS('Gamma Data'!C11))/MAX(ABS('Gamma Data'!A11-$J$6)/($J$6*0.005),1)+ROW()/1000000000)))
A12: =IF('Gamma Data'!A12="","",'Gamma Data'!A12) | B12: =IF(A12="","",'Gamma Data'!B12-'Gamma Data'!C12) | C12: =IF(A12="","",ABS('Gamma Data'!B12)+ABS('Gamma Data'!C12)) | D12: =IF(A12="","",IF(C12=0,"-",IF(AND('Gamma Data'!B12>0,'Gamma Data'!B12>='Gamma Data'!C12*1.5),"Call Wall",IF(AND('Gamma Data'!C12>0,'Gamma Data'!C12>='Gamma Data'!B12*1.5),"Put Wall","(mixed)")))) | E12: =IF(OR(A12="",$J$12=0),"",C12/$J$12) | F12: =IF(A12="","",IF(C12>=2*$J$12,"จุดหนืด",IF(C12<=0.5*$J$12,"air pocket",""))) | H12: =IF(AND(A12>=$J$6,'Gamma Data'!B12>0,'Gamma Data'!B12>='Gamma Data'!C12*1.5),'Gamma Data'!B12,0) | I12: ค่ากลาง Gross | J12: {=MEDIAN(IF(ISNUMBER('Gamma Data'!$A$2:$A$152),ABS('Gamma Data'!$B$2:$B$152)+ABS('Gamma Data'!$C$2:$C$152)))} | AB12: =IF(NOT(ISNUMBER('Gamma Data'!A12)),"",IF((ABS('Gamma Data'!B12)+ABS('Gamma Data'!C12))=0,"",IF(OR(ABS('Gamma Data'!A12-$J$6)>$J$6*$J$26,ABS('Gamma Data'!A12-$J$6)<$J$28),"",(ABS('Gamma Data'!B12)+ABS('Gamma Data'!C12))/MAX(ABS('Gamma Data'!A12-$J$6)/($J$6*0.005),1)+ROW()/1000000000)))
A13: =IF('Gamma Data'!A13="","",'Gamma Data'!A13) | B13: =IF(A13="","",'Gamma Data'!B13-'Gamma Data'!C13) | C13: =IF(A13="","",ABS('Gamma Data'!B13)+ABS('Gamma Data'!C13)) | D13: =IF(A13="","",IF(C13=0,"-",IF(AND('Gamma Data'!B13>0,'Gamma Data'!B13>='Gamma Data'!C13*1.5),"Call Wall",IF(AND('Gamma Data'!C13>0,'Gamma Data'!C13>='Gamma Data'!B13*1.5),"Put Wall","(mixed)")))) | E13: =IF(OR(A13="",$J$12=0),"",C13/$J$12) | F13: =IF(A13="","",IF(C13>=2*$J$12,"จุดหนืด",IF(C13<=0.5*$J$12,"air pocket",""))) | H13: =IF(AND(A13>=$J$6,'Gamma Data'!B13>0,'Gamma Data'!B13>='Gamma Data'!C13*1.5),'Gamma Data'!B13,0) | I13: =IF(AND(A13<=$J$6,'Gamma Data'!C13>0,'Gamma Data'!C13>='Gamma Data'!B13*1.5),'Gamma Data'!C13,0) | AB13: =IF(NOT(ISNUMBER('Gamma Data'!A13)),"",IF((ABS('Gamma Data'!B13)+ABS('Gamma Data'!C13))=0,"",IF(OR(ABS('Gamma Data'!A13-$J$6)>$J$6*$J$26,ABS('Gamma Data'!A13-$J$6)<$J$28),"",(ABS('Gamma Data'!B13)+ABS('Gamma Data'!C13))/MAX(ABS('Gamma Data'!A13-$J$6)/($J$6*0.005),1)+ROW()/1000000000)))
A14: =IF('Gamma Data'!A14="","",'Gamma Data'!A14) | B14: =IF(A14="","",'Gamma Data'!B14-'Gamma Data'!C14) | C14: =IF(A14="","",ABS('Gamma Data'!B14)+ABS('Gamma Data'!C14)) | D14: =IF(A14="","",IF(C14=0,"-",IF(AND('Gamma Data'!B14>0,'Gamma Data'!B14>='Gamma Data'!C14*1.5),"Call Wall",IF(AND('Gamma Data'!C14>0,'Gamma Data'!C14>='Gamma Data'!B14*1.5),"Put Wall","(mixed)")))) | E14: =IF(OR(A14="",$J$12=0),"",C14/$J$12) | F14: =IF(A14="","",IF(C14>=2*$J$12,"จุดหนืด",IF(C14<=0.5*$J$12,"air pocket",""))) | H14: =IF(AND(A14>=$J$6,'Gamma Data'!B14>0,'Gamma Data'!B14>='Gamma Data'!C14*1.5),'Gamma Data'!B14,0) | I14: ── ตรวจความครบของข้อมูล ── | AB14: =IF(NOT(ISNUMBER('Gamma Data'!A14)),"",IF((ABS('Gamma Data'!B14)+ABS('Gamma Data'!C14))=0,"",IF(OR(ABS('Gamma Data'!A14-$J$6)>$J$6*$J$26,ABS('Gamma Data'!A14-$J$6)<$J$28),"",(ABS('Gamma Data'!B14)+ABS('Gamma Data'!C14))/MAX(ABS('Gamma Data'!A14-$J$6)/($J$6*0.005),1)+ROW()/1000000000)))
A15: =IF('Gamma Data'!A15="","",'Gamma Data'!A15) | B15: =IF(A15="","",'Gamma Data'!B15-'Gamma Data'!C15) | C15: =IF(A15="","",ABS('Gamma Data'!B15)+ABS('Gamma Data'!C15)) | D15: =IF(A15="","",IF(C15=0,"-",IF(AND('Gamma Data'!B15>0,'Gamma Data'!B15>='Gamma Data'!C15*1.5),"Call Wall",IF(AND('Gamma Data'!C15>0,'Gamma Data'!C15>='Gamma Data'!B15*1.5),"Put Wall","(mixed)")))) | E15: =IF(OR(A15="",$J$12=0),"",C15/$J$12) | F15: =IF(A15="","",IF(C15>=2*$J$12,"จุดหนืด",IF(C15<=0.5*$J$12,"air pocket",""))) | H15: =IF(AND(A15>=$J$6,'Gamma Data'!B15>0,'Gamma Data'!B15>='Gamma Data'!C15*1.5),'Gamma Data'!B15,0) | I15: ขอบบนเป็น 0? | J15: =IF(AND('Gamma Data'!B2=0,'Gamma Data'!C2=0),"ครบ","ยังไม่ครบ - ขยาย Strikes") | AB15: =IF(NOT(ISNUMBER('Gamma Data'!A15)),"",IF((ABS('Gamma Data'!B15)+ABS('Gamma Data'!C15))=0,"",IF(OR(ABS('Gamma Data'!A15-$J$6)>$J$6*$J$26,ABS('Gamma Data'!A15-$J$6)<$J$28),"",(ABS('Gamma Data'!B15)+ABS('Gamma Data'!C15))/MAX(ABS('Gamma Data'!A15-$J$6)/($J$6*0.005),1)+ROW()/1000000000)))
A16: =IF('Gamma Data'!A16="","",'Gamma Data'!A16) | B16: =IF(A16="","",'Gamma Data'!B16-'Gamma Data'!C16) | C16: =IF(A16="","",ABS('Gamma Data'!B16)+ABS('Gamma Data'!C16)) | D16: =IF(A16="","",IF(C16=0,"-",IF(AND('Gamma Data'!B16>0,'Gamma Data'!B16>='Gamma Data'!C16*1.5),"Call Wall",IF(AND('Gamma Data'!C16>0,'Gamma Data'!C16>='Gamma Data'!B16*1.5),"Put Wall","(mixed)")))) | E16: =IF(OR(A16="",$J$12=0),"",C16/$J$12) | F16: =IF(A16="","",IF(C16>=2*$J$12,"จุดหนืด",IF(C16<=0.5*$J$12,"air pocket",""))) | H16: =IF(AND(A16>=$J$6,'Gamma Data'!B16>0,'Gamma Data'!B16>='Gamma Data'!C16*1.5),'Gamma Data'!B16,0) | I16: ขอบล่างเป็น 0? | J16: =IF(AND(INDEX('Gamma Data'!$B$2:$B$152,COUNT('Gamma Data'!$A$2:$A$152))=0,INDEX('Gamma Data'!$C$2:$C$152,COUNT('Gamma Data'!$A$2:$A$152))=0),"ครบ","ยังไม่ครบ - ขยาย Strikes") | AB16: =IF(NOT(ISNUMBER('Gamma Data'!A16)),"",IF((ABS('Gamma Data'!B16)+ABS('Gamma Data'!C16))=0,"",IF(OR(ABS('Gamma Data'!A16-$J$6)>$J$6*$J$26,ABS('Gamma Data'!A16-$J$6)<$J$28),"",(ABS('Gamma Data'!B16)+ABS('Gamma Data'!C16))/MAX(ABS('Gamma Data'!A16-$J$6)/($J$6*0.005),1)+ROW()/1000000000)))
A17: =IF('Gamma Data'!A17="","",'Gamma Data'!A17) | B17: =IF(A17="","",'Gamma Data'!B17-'Gamma Data'!C17) | C17: =IF(A17="","",ABS('Gamma Data'!B17)+ABS('Gamma Data'!C17)) | D17: =IF(A17="","",IF(C17=0,"-",IF(AND('Gamma Data'!B17>0,'Gamma Data'!B17>='Gamma Data'!C17*1.5),"Call Wall",IF(AND('Gamma Data'!C17>0,'Gamma Data'!C17>='Gamma Data'!B17*1.5),"Put Wall","(mixed)")))) | E17: =IF(OR(A17="",$J$12=0),"",C17/$J$12) | F17: =IF(A17="","",IF(C17>=2*$J$12,"จุดหนืด",IF(C17<=0.5*$J$12,"air pocket",""))) | H17: =IF(AND(A17>=$J$6,'Gamma Data'!B17>0,'Gamma Data'!B17>='Gamma Data'!C17*1.5),'Gamma Data'!B17,0) | I17: จำนวนแถวที่คำนวณ | J17: =COUNT('Gamma Data'!$A$2:$A$152) | AB17: =IF(NOT(ISNUMBER('Gamma Data'!A17)),"",IF((ABS('Gamma Data'!B17)+ABS('Gamma Data'!C17))=0,"",IF(OR(ABS('Gamma Data'!A17-$J$6)>$J$6*$J$26,ABS('Gamma Data'!A17-$J$6)<$J$28),"",(ABS('Gamma Data'!B17)+ABS('Gamma Data'!C17))/MAX(ABS('Gamma Data'!A17-$J$6)/($J$6*0.005),1)+ROW()/1000000000)))
A18: =IF('Gamma Data'!A18="","",'Gamma Data'!A18) | B18: =IF(A18="","",'Gamma Data'!B18-'Gamma Data'!C18) | C18: =IF(A18="","",ABS('Gamma Data'!B18)+ABS('Gamma Data'!C18)) | D18: =IF(A18="","",IF(C18=0,"-",IF(AND('Gamma Data'!B18>0,'Gamma Data'!B18>='Gamma Data'!C18*1.5),"Call Wall",IF(AND('Gamma Data'!C18>0,'Gamma Data'!C18>='Gamma Data'!B18*1.5),"Put Wall","(mixed)")))) | E18: =IF(OR(A18="",$J$12=0),"",C18/$J$12) | F18: =IF(A18="","",IF(C18>=2*$J$12,"จุดหนืด",IF(C18<=0.5*$J$12,"air pocket",""))) | H18: =IF(AND(A18>=$J$6,'Gamma Data'!B18>0,'Gamma Data'!B18>='Gamma Data'!C18*1.5),'Gamma Data'!B18,0) | I18: CONVICTION | J18: {=IF(SUMPRODUCT(ABS('Gamma Data'!$B$2:$B$152-'Gamma Data'!$C$2:$C$152))=0,"",ABS(J4)/SUMPRODUCT(ABS('Gamma Data'!$B$2:$B$152-'Gamma Data'!$C$2:$C$152)))} | AB18: =IF(NOT(ISNUMBER('Gamma Data'!A18)),"",IF((ABS('Gamma Data'!B18)+ABS('Gamma Data'!C18))=0,"",IF(OR(ABS('Gamma Data'!A18-$J$6)>$J$6*$J$26,ABS('Gamma Data'!A18-$J$6)<$J$28),"",(ABS('Gamma Data'!B18)+ABS('Gamma Data'!C18))/MAX(ABS('Gamma Data'!A18-$J$6)/($J$6*0.005),1)+ROW()/1000000000)))
A19: =IF('Gamma Data'!A19="","",'Gamma Data'!A19) | B19: =IF(A19="","",'Gamma Data'!B19-'Gamma Data'!C19) | C19: =IF(A19="","",ABS('Gamma Data'!B19)+ABS('Gamma Data'!C19)) | D19: =IF(A19="","",IF(C19=0,"-",IF(AND('Gamma Data'!B19>0,'Gamma Data'!B19>='Gamma Data'!C19*1.5),"Call Wall",IF(AND('Gamma Data'!C19>0,'Gamma Data'!C19>='Gamma Data'!B19*1.5),"Put Wall","(mixed)")))) | E19: =IF(OR(A19="",$J$12=0),"",C19/$J$12) | F19: =IF(A19="","",IF(C19>=2*$J$12,"จุดหนืด",IF(C19<=0.5*$J$12,"air pocket",""))) | H19: =IF(AND(A19>=$J$6,'Gamma Data'!B19>0,'Gamma Data'!B19>='Gamma Data'!C19*1.5),'Gamma Data'!B19,0) | J19: =IF(J18="","",IF(J18<0.05,"อ่อนมาก - ยังใช้งานไม่ได้",IF(J18<0.15,"อ่อน - ใช้ประกอบได้แต่อย่าพึ่งพา",IF(J18<0.3,"พอใช้ได้","ชัดเจน - เชื่อถือได้")))) | AB19: =IF(NOT(ISNUMBER('Gamma Data'!A19)),"",IF((ABS('Gamma Data'!B19)+ABS('Gamma Data'!C19))=0,"",IF(OR(ABS('Gamma Data'!A19-$J$6)>$J$6*$J$26,ABS('Gamma Data'!A19-$J$6)<$J$28),"",(ABS('Gamma Data'!B19)+ABS('Gamma Data'!C19))/MAX(ABS('Gamma Data'!A19-$J$6)/($J$6*0.005),1)+ROW()/1000000000)))
A20: =IF('Gamma Data'!A20="","",'Gamma Data'!A20) | B20: =IF(A20="","",'Gamma Data'!B20-'Gamma Data'!C20) | C20: =IF(A20="","",ABS('Gamma Data'!B20)+ABS('Gamma Data'!C20)) | D20: =IF(A20="","",IF(C20=0,"-",IF(AND('Gamma Data'!B20>0,'Gamma Data'!B20>='Gamma Data'!C20*1.5),"Call Wall",IF(AND('Gamma Data'!C20>0,'Gamma Data'!C20>='Gamma Data'!B20*1.5),"Put Wall","(mixed)")))) | E20: =IF(OR(A20="",$J$12=0),"",C20/$J$12) | F20: =IF(A20="","",IF(C20>=2*$J$12,"จุดหนืด",IF(C20<=0.5*$J$12,"air pocket",""))) | H20: =IF(AND(A20>=$J$6,'Gamma Data'!B20>0,'Gamma Data'!B20>='Gamma Data'!C20*1.5),'Gamma Data'!B20,0) | AB20: =IF(NOT(ISNUMBER('Gamma Data'!A20)),"",IF((ABS('Gamma Data'!B20)+ABS('Gamma Data'!C20))=0,"",IF(OR(ABS('Gamma Data'!A20-$J$6)>$J$6*$J$26,ABS('Gamma Data'!A20-$J$6)<$J$28),"",(ABS('Gamma Data'!B20)+ABS('Gamma Data'!C20))/MAX(ABS('Gamma Data'!A20-$J$6)/($J$6*0.005),1)+ROW()/1000000000)))
A21: =IF('Gamma Data'!A21="","",'Gamma Data'!A21) | B21: =IF(A21="","",'Gamma Data'!B21-'Gamma Data'!C21) | C21: =IF(A21="","",ABS('Gamma Data'!B21)+ABS('Gamma Data'!C21)) | D21: =IF(A21="","",IF(C21=0,"-",IF(AND('Gamma Data'!B21>0,'Gamma Data'!B21>='Gamma Data'!C21*1.5),"Call Wall",IF(AND('Gamma Data'!C21>0,'Gamma Data'!C21>='Gamma Data'!B21*1.5),"Put Wall","(mixed)")))) | E21: =IF(OR(A21="",$J$12=0),"",C21/$J$12) | F21: =IF(A21="","",IF(C21>=2*$J$12,"จุดหนืด",IF(C21<=0.5*$J$12,"air pocket",""))) | H21: =IF(AND(A21>=$J$6,'Gamma Data'!B21>0,'Gamma Data'!B21>='Gamma Data'!C21*1.5),'Gamma Data'!B21,0) | AB21: =IF(NOT(ISNUMBER('Gamma Data'!A21)),"",IF((ABS('Gamma Data'!B21)+ABS('Gamma Data'!C21))=0,"",IF(OR(ABS('Gamma Data'!A21-$J$6)>$J$6*$J$26,ABS('Gamma Data'!A21-$J$6)<$J$28),"",(ABS('Gamma Data'!B21)+ABS('Gamma Data'!C21))/MAX(ABS('Gamma Data'!A21-$J$6)/($J$6*0.005),1)+ROW()/1000000000)))
A22: =IF('Gamma Data'!A22="","",'Gamma Data'!A22) | B22: =IF(A22="","",'Gamma Data'!B22-'Gamma Data'!C22) | C22: =IF(A22="","",ABS('Gamma Data'!B22)+ABS('Gamma Data'!C22)) | D22: =IF(A22="","",IF(C22=0,"-",IF(AND('Gamma Data'!B22>0,'Gamma Data'!B22>='Gamma Data'!C22*1.5),"Call Wall",IF(AND('Gamma Data'!C22>0,'Gamma Data'!C22>='Gamma Data'!B22*1.5),"Put Wall","(mixed)")))) | E22: =IF(OR(A22="",$J$12=0),"",C22/$J$12) | F22: =IF(A22="","",IF(C22>=2*$J$12,"จุดหนืด",IF(C22<=0.5*$J$12,"air pocket",""))) | H22: =IF(AND(A22>=$J$6,'Gamma Data'!B22>0,'Gamma Data'!B22>='Gamma Data'!C22*1.5),'Gamma Data'!B22,0) | AB22: =IF(NOT(ISNUMBER('Gamma Data'!A22)),"",IF((ABS('Gamma Data'!B22)+ABS('Gamma Data'!C22))=0,"",IF(OR(ABS('Gamma Data'!A22-$J$6)>$J$6*$J$26,ABS('Gamma Data'!A22-$J$6)<$J$28),"",(ABS('Gamma Data'!B22)+ABS('Gamma Data'!C22))/MAX(ABS('Gamma Data'!A22-$J$6)/($J$6*0.005),1)+ROW()/1000000000)))
A23: =IF('Gamma Data'!A23="","",'Gamma Data'!A23) | B23: =IF(A23="","",'Gamma Data'!B23-'Gamma Data'!C23) | C23: =IF(A23="","",ABS('Gamma Data'!B23)+ABS('Gamma Data'!C23)) | D23: =IF(A23="","",IF(C23=0,"-",IF(AND('Gamma Data'!B23>0,'Gamma Data'!B23>='Gamma Data'!C23*1.5),"Call Wall",IF(AND('Gamma Data'!C23>0,'Gamma Data'!C23>='Gamma Data'!B23*1.5),"Put Wall","(mixed)")))) | E23: =IF(OR(A23="",$J$12=0),"",C23/$J$12) | F23: =IF(A23="","",IF(C23>=2*$J$12,"จุดหนืด",IF(C23<=0.5*$J$12,"air pocket",""))) | H23: =IF(AND(A23>=$J$6,'Gamma Data'!B23>0,'Gamma Data'!B23>='Gamma Data'!C23*1.5),'Gamma Data'!B23,0) | AB23: =IF(NOT(ISNUMBER('Gamma Data'!A23)),"",IF((ABS('Gamma Data'!B23)+ABS('Gamma Data'!C23))=0,"",IF(OR(ABS('Gamma Data'!A23-$J$6)>$J$6*$J$26,ABS('Gamma Data'!A23-$J$6)<$J$28),"",(ABS('Gamma Data'!B23)+ABS('Gamma Data'!C23))/MAX(ABS('Gamma Data'!A23-$J$6)/($J$6*0.005),1)+ROW()/1000000000)))
A24: =IF('Gamma Data'!A24="","",'Gamma Data'!A24) | B24: =IF(A24="","",'Gamma Data'!B24-'Gamma Data'!C24) | C24: =IF(A24="","",ABS('Gamma Data'!B24)+ABS('Gamma Data'!C24)) | D24: =IF(A24="","",IF(C24=0,"-",IF(AND('Gamma Data'!B24>0,'Gamma Data'!B24>='Gamma Data'!C24*1.5),"Call Wall",IF(AND('Gamma Data'!C24>0,'Gamma Data'!C24>='Gamma Data'!B24*1.5),"Put Wall","(mixed)")))) | E24: =IF(OR(A24="",$J$12=0),"",C24/$J$12) | F24: =IF(A24="","",IF(C24>=2*$J$12,"จุดหนืด",IF(C24<=0.5*$J$12,"air pocket",""))) | H24: =IF(AND(A24>=$J$6,'Gamma Data'!B24>0,'Gamma Data'!B24>='Gamma Data'!C24*1.5),'Gamma Data'!B24,0) | AB24: =IF(NOT(ISNUMBER('Gamma Data'!A24)),"",IF((ABS('Gamma Data'!B24)+ABS('Gamma Data'!C24))=0,"",IF(OR(ABS('Gamma Data'!A24-$J$6)>$J$6*$J$26,ABS('Gamma Data'!A24-$J$6)<$J$28),"",(ABS('Gamma Data'!B24)+ABS('Gamma Data'!C24))/MAX(ABS('Gamma Data'!A24-$J$6)/($J$6*0.005),1)+ROW()/1000000000)))
A25: =IF('Gamma Data'!A25="","",'Gamma Data'!A25) | B25: =IF(A25="","",'Gamma Data'!B25-'Gamma Data'!C25) | C25: =IF(A25="","",ABS('Gamma Data'!B25)+ABS('Gamma Data'!C25)) | D25: =IF(A25="","",IF(C25=0,"-",IF(AND('Gamma Data'!B25>0,'Gamma Data'!B25>='Gamma Data'!C25*1.5),"Call Wall",IF(AND('Gamma Data'!C25>0,'Gamma Data'!C25>='Gamma Data'!B25*1.5),"Put Wall","(mixed)")))) | E25: =IF(OR(A25="",$J$12=0),"",C25/$J$12) | F25: =IF(A25="","",IF(C25>=2*$J$12,"จุดหนืด",IF(C25<=0.5*$J$12,"air pocket",""))) | H25: =IF(AND(A25>=$J$6,'Gamma Data'!B25>0,'Gamma Data'!B25>='Gamma Data'!C25*1.5),'Gamma Data'!B25,0) | I25: ── Pins (แม่เหล็ก) ── | AB25: =IF(NOT(ISNUMBER('Gamma Data'!A25)),"",IF((ABS('Gamma Data'!B25)+ABS('Gamma Data'!C25))=0,"",IF(OR(ABS('Gamma Data'!A25-$J$6)>$J$6*$J$26,ABS('Gamma Data'!A25-$J$6)<$J$28),"",(ABS('Gamma Data'!B25)+ABS('Gamma Data'!C25))/MAX(ABS('Gamma Data'!A25-$J$6)/($J$6*0.005),1)+ROW()/1000000000)))
A26: =IF('Gamma Data'!A26="","",'Gamma Data'!A26) | B26: =IF(A26="","",'Gamma Data'!B26-'Gamma Data'!C26) | C26: =IF(A26="","",ABS('Gamma Data'!B26)+ABS('Gamma Data'!C26)) | D26: =IF(A26="","",IF(C26=0,"-",IF(AND('Gamma Data'!B26>0,'Gamma Data'!B26>='Gamma Data'!C26*1.5),"Call Wall",IF(AND('Gamma Data'!C26>0,'Gamma Data'!C26>='Gamma Data'!B26*1.5),"Put Wall","(mixed)")))) | E26: =IF(OR(A26="",$J$12=0),"",C26/$J$12) | F26: =IF(A26="","",IF(C26>=2*$J$12,"จุดหนืด",IF(C26<=0.5*$J$12,"air pocket",""))) | H26: =IF(AND(A26>=$J$6,'Gamma Data'!B26>0,'Gamma Data'!B26>='Gamma Data'!C26*1.5),'Gamma Data'!B26,0) | I26: ช่วงค้นหา (± % ของราคา) | J26: 0.05 | AB26: =IF(NOT(ISNUMBER('Gamma Data'!A26)),"",IF((ABS('Gamma Data'!B26)+ABS('Gamma Data'!C26))=0,"",IF(OR(ABS('Gamma Data'!A26-$J$6)>$J$6*$J$26,ABS('Gamma Data'!A26-$J$6)<$J$28),"",(ABS('Gamma Data'!B26)+ABS('Gamma Data'!C26))/MAX(ABS('Gamma Data'!A26-$J$6)/($J$6*0.005),1)+ROW()/1000000000)))
A27: =IF('Gamma Data'!A27="","",'Gamma Data'!A27) | B27: =IF(A27="","",'Gamma Data'!B27-'Gamma Data'!C27) | C27: =IF(A27="","",ABS('Gamma Data'!B27)+ABS('Gamma Data'!C27)) | D27: =IF(A27="","",IF(C27=0,"-",IF(AND('Gamma Data'!B27>0,'Gamma Data'!B27>='Gamma Data'!C27*1.5),"Call Wall",IF(AND('Gamma Data'!C27>0,'Gamma Data'!C27>='Gamma Data'!B27*1.5),"Put Wall","(mixed)")))) | E27: =IF(OR(A27="",$J$12=0),"",C27/$J$12) | F27: =IF(A27="","",IF(C27>=2*$J$12,"จุดหนืด",IF(C27<=0.5*$J$12,"air pocket",""))) | H27: =IF(AND(A27>=$J$6,'Gamma Data'!B27>0,'Gamma Data'!B27>='Gamma Data'!C27*1.5),'Gamma Data'!B27,0) | I27: สถานะแรงดูด | J27: =IF(SUMPRODUCT(ABS('Gamma Data'!$B$2:$B$152-'Gamma Data'!$C$2:$C$152))=0,"",IF(ABS((SUM('Gamma Data'!$B$2:$B$152)-SUM('Gamma Data'!$C$2:$C$152)))/SUMPRODUCT(ABS('Gamma Data'!$B$2:$B$152-'Gamma Data'!$C$2:$C$152))<0.05,"กระดานสมดุล - แรงดูดไม่ชัด",IF((SUM('Gamma Data'!$B$2:$B$152)-SUM('Gamma Data'!$C$2:$C$152))>0,"มีแรงดูด - โหมด Positive GEX","ไม่มีแรงดูด - โหมดลบ ใช้เป็นเส้นอ้างอิง"))) | AB27: =IF(NOT(ISNUMBER('Gamma Data'!A27)),"",IF((ABS('Gamma Data'!B27)+ABS('Gamma Data'!C27))=0,"",IF(OR(ABS('Gamma Data'!A27-$J$6)>$J$6*$J$26,ABS('Gamma Data'!A27-$J$6)<$J$28),"",(ABS('Gamma Data'!B27)+ABS('Gamma Data'!C27))/MAX(ABS('Gamma Data'!A27-$J$6)/($J$6*0.005),1)+ROW()/1000000000)))
A28: =IF('Gamma Data'!A28="","",'Gamma Data'!A28) | B28: =IF(A28="","",'Gamma Data'!B28-'Gamma Data'!C28) | C28: =IF(A28="","",ABS('Gamma Data'!B28)+ABS('Gamma Data'!C28)) | D28: =IF(A28="","",IF(C28=0,"-",IF(AND('Gamma Data'!B28>0,'Gamma Data'!B28>='Gamma Data'!C28*1.5),"Call Wall",IF(AND('Gamma Data'!C28>0,'Gamma Data'!C28>='Gamma Data'!B28*1.5),"Put Wall","(mixed)")))) | E28: =IF(OR(A28="",$J$12=0),"",C28/$J$12) | F28: =IF(A28="","",IF(C28>=2*$J$12,"จุดหนืด",IF(C28<=0.5*$J$12,"air pocket",""))) | H28: =IF(AND(A28>=$J$6,'Gamma Data'!B28>0,'Gamma Data'!B28>='Gamma Data'!C28*1.5),'Gamma Data'!B28,0) | I28: ระยะขั้นต่ำจากราคา ($) | J28: 25 | AB28: =IF(NOT(ISNUMBER('Gamma Data'!A28)),"",IF((ABS('Gamma Data'!B28)+ABS('Gamma Data'!C28))=0,"",IF(OR(ABS('Gamma Data'!A28-$J$6)>$J$6*$J$26,ABS('Gamma Data'!A28-$J$6)<$J$28),"",(ABS('Gamma Data'!B28)+ABS('Gamma Data'!C28))/MAX(ABS('Gamma Data'!A28-$J$6)/($J$6*0.005),1)+ROW()/1000000000)))
A29: =IF('Gamma Data'!A29="","",'Gamma Data'!A29) | B29: =IF(A29="","",'Gamma Data'!B29-'Gamma Data'!C29) | C29: =IF(A29="","",ABS('Gamma Data'!B29)+ABS('Gamma Data'!C29)) | D29: =IF(A29="","",IF(C29=0,"-",IF(AND('Gamma Data'!B29>0,'Gamma Data'!B29>='Gamma Data'!C29*1.5),"Call Wall",IF(AND('Gamma Data'!C29>0,'Gamma Data'!C29>='Gamma Data'!B29*1.5),"Put Wall","(mixed)")))) | E29: =IF(OR(A29="",$J$12=0),"",C29/$J$12) | F29: =IF(A29="","",IF(C29>=2*$J$12,"จุดหนืด",IF(C29<=0.5*$J$12,"air pocket",""))) | H29: =IF(AND(A29>=$J$6,'Gamma Data'!B29>0,'Gamma Data'!B29>='Gamma Data'!C29*1.5),'Gamma Data'!B29,0) | I29: อันดับ | J29: Strike | K29: Gross Gamma | L29: ห่างราคา | M29: ฝั่งที่เด่น | AB29: =IF(NOT(ISNUMBER('Gamma Data'!A29)),"",IF((ABS('Gamma Data'!B29)+ABS('Gamma Data'!C29))=0,"",IF(OR(ABS('Gamma Data'!A29-$J$6)>$J$6*$J$26,ABS('Gamma Data'!A29-$J$6)<$J$28),"",(ABS('Gamma Data'!B29)+ABS('Gamma Data'!C29))/MAX(ABS('Gamma Data'!A29-$J$6)/($J$6*0.005),1)+ROW()/1000000000)))
A30: =IF('Gamma Data'!A30="","",'Gamma Data'!A30) | B30: =IF(A30="","",'Gamma Data'!B30-'Gamma Data'!C30) | C30: =IF(A30="","",ABS('Gamma Data'!B30)+ABS('Gamma Data'!C30)) | D30: =IF(A30="","",IF(C30=0,"-",IF(AND('Gamma Data'!B30>0,'Gamma Data'!B30>='Gamma Data'!C30*1.5),"Call Wall",IF(AND('Gamma Data'!C30>0,'Gamma Data'!C30>='Gamma Data'!B30*1.5),"Put Wall","(mixed)")))) | E30: =IF(OR(A30="",$J$12=0),"",C30/$J$12) | F30: =IF(A30="","",IF(C30>=2*$J$12,"จุดหนืด",IF(C30<=0.5*$J$12,"air pocket",""))) | H30: =IF(AND(A30>=$J$6,'Gamma Data'!B30>0,'Gamma Data'!B30>='Gamma Data'!C30*1.5),'Gamma Data'!B30,0) | I30: 1 | J30: =IF(COUNT($AB$2:$AB$152)<1,"",INDEX('Gamma Data'!$A$2:$A$152,MATCH(LARGE($AB$2:$AB$152,1),$AB$2:$AB$152,0))) | K30: =IF(J30="","",ABS(INDEX('Gamma Data'!$B$2:$B$152,MATCH(J30,'Gamma Data'!$A$2:$A$152,0)))+ABS(INDEX('Gamma Data'!$C$2:$C$152,MATCH(J30,'Gamma Data'!$A$2:$A$152,0)))) | L30: =IF(J30="","",J30-$J$6) | M30: =IF(J30="","",IF(AND(INDEX('Gamma Data'!$B$2:$B$152,MATCH(J30,'Gamma Data'!$A$2:$A$152,0))>0,INDEX('Gamma Data'!$B$2:$B$152,MATCH(J30,'Gamma Data'!$A$2:$A$152,0))>=INDEX('Gamma Data'!$C$2:$C$152,MATCH(J30,'Gamma Data'!$A$2:$A$152,0))*1.5),"Call เด่น",IF(AND(INDEX('Gamma Data'!$C$2:$C$152,MATCH(J30,'Gamma Data'!$A$2:$A$152,0))>0,INDEX('Gamma Data'!$C$2:$C$152,MATCH(J30,'Gamma Data'!$A$2:$A$152,0))>=INDEX('Gamma Data'!$B$2:$B$152,MATCH(J30,'Gamma Data'!$A$2:$A$152,0))*1.5),"Put เด่น","(mixed)"))) | AB30: =IF(NOT(ISNUMBER('Gamma Data'!A30)),"",IF((ABS('Gamma Data'!B30)+ABS('Gamma Data'!C30))=0,"",IF(OR(ABS('Gamma Data'!A30-$J$6)>$J$6*$J$26,ABS('Gamma Data'!A30-$J$6)<$J$28),"",(ABS('Gamma Data'!B30)+ABS('Gamma Data'!C30))/MAX(ABS('Gamma Data'!A30-$J$6)/($J$6*0.005),1)+ROW()/1000000000)))
A31: =IF('Gamma Data'!A31="","",'Gamma Data'!A31) | B31: =IF(A31="","",'Gamma Data'!B31-'Gamma Data'!C31) | C31: =IF(A31="","",ABS('Gamma Data'!B31)+ABS('Gamma Data'!C31)) | D31: =IF(A31="","",IF(C31=0,"-",IF(AND('Gamma Data'!B31>0,'Gamma Data'!B31>='Gamma Data'!C31*1.5),"Call Wall",IF(AND('Gamma Data'!C31>0,'Gamma Data'!C31>='Gamma Data'!B31*1.5),"Put Wall","(mixed)")))) | E31: =IF(OR(A31="",$J$12=0),"",C31/$J$12) | F31: =IF(A31="","",IF(C31>=2*$J$12,"จุดหนืด",IF(C31<=0.5*$J$12,"air pocket",""))) | H31: =IF(AND(A31>=$J$6,'Gamma Data'!B31>0,'Gamma Data'!B31>='Gamma Data'!C31*1.5),'Gamma Data'!B31,0) | I31: 2 | J31: =IF(COUNT($AB$2:$AB$152)<2,"",INDEX('Gamma Data'!$A$2:$A$152,MATCH(LARGE($AB$2:$AB$152,2),$AB$2:$AB$152,0))) | K31: =IF(J31="","",ABS(INDEX('Gamma Data'!$B$2:$B$152,MATCH(J31,'Gamma Data'!$A$2:$A$152,0)))+ABS(INDEX('Gamma Data'!$C$2:$C$152,MATCH(J31,'Gamma Data'!$A$2:$A$152,0)))) | L31: =IF(J31="","",J31-$J$6) | M31: =IF(J31="","",IF(AND(INDEX('Gamma Data'!$B$2:$B$152,MATCH(J31,'Gamma Data'!$A$2:$A$152,0))>0,INDEX('Gamma Data'!$B$2:$B$152,MATCH(J31,'Gamma Data'!$A$2:$A$152,0))>=INDEX('Gamma Data'!$C$2:$C$152,MATCH(J31,'Gamma Data'!$A$2:$A$152,0))*1.5),"Call เด่น",IF(AND(INDEX('Gamma Data'!$C$2:$C$152,MATCH(J31,'Gamma Data'!$A$2:$A$152,0))>0,INDEX('Gamma Data'!$C$2:$C$152,MATCH(J31,'Gamma Data'!$A$2:$A$152,0))>=INDEX('Gamma Data'!$B$2:$B$152,MATCH(J31,'Gamma Data'!$A$2:$A$152,0))*1.5),"Put เด่น","(mixed)"))) | AB31: =IF(NOT(ISNUMBER('Gamma Data'!A31)),"",IF((ABS('Gamma Data'!B31)+ABS('Gamma Data'!C31))=0,"",IF(OR(ABS('Gamma Data'!A31-$J$6)>$J$6*$J$26,ABS('Gamma Data'!A31-$J$6)<$J$28),"",(ABS('Gamma Data'!B31)+ABS('Gamma Data'!C31))/MAX(ABS('Gamma Data'!A31-$J$6)/($J$6*0.005),1)+ROW()/1000000000)))
A32: =IF('Gamma Data'!A32="","",'Gamma Data'!A32) | B32: =IF(A32="","",'Gamma Data'!B32-'Gamma Data'!C32) | C32: =IF(A32="","",ABS('Gamma Data'!B32)+ABS('Gamma Data'!C32)) | D32: =IF(A32="","",IF(C32=0,"-",IF(AND('Gamma Data'!B32>0,'Gamma Data'!B32>='Gamma Data'!C32*1.5),"Call Wall",IF(AND('Gamma Data'!C32>0,'Gamma Data'!C32>='Gamma Data'!B32*1.5),"Put Wall","(mixed)")))) | E32: =IF(OR(A32="",$J$12=0),"",C32/$J$12) | F32: =IF(A32="","",IF(C32>=2*$J$12,"จุดหนืด",IF(C32<=0.5*$J$12,"air pocket",""))) | H32: =IF(AND(A32>=$J$6,'Gamma Data'!B32>0,'Gamma Data'!B32>='Gamma Data'!C32*1.5),'Gamma Data'!B32,0) | I32: 3 | J32: =IF(COUNT($AB$2:$AB$152)<3,"",INDEX('Gamma Data'!$A$2:$A$152,MATCH(LARGE($AB$2:$AB$152,3),$AB$2:$AB$152,0))) | K32: =IF(J32="","",ABS(INDEX('Gamma Data'!$B$2:$B$152,MATCH(J32,'Gamma Data'!$A$2:$A$152,0)))+ABS(INDEX('Gamma Data'!$C$2:$C$152,MATCH(J32,'Gamma Data'!$A$2:$A$152,0)))) | L32: =IF(J32="","",J32-$J$6) | M32: =IF(J32="","",IF(AND(INDEX('Gamma Data'!$B$2:$B$152,MATCH(J32,'Gamma Data'!$A$2:$A$152,0))>0,INDEX('Gamma Data'!$B$2:$B$152,MATCH(J32,'Gamma Data'!$A$2:$A$152,0))>=INDEX('Gamma Data'!$C$2:$C$152,MATCH(J32,'Gamma Data'!$A$2:$A$152,0))*1.5),"Call เด่น",IF(AND(INDEX('Gamma Data'!$C$2:$C$152,MATCH(J32,'Gamma Data'!$A$2:$A$152,0))>0,INDEX('Gamma Data'!$C$2:$C$152,MATCH(J32,'Gamma Data'!$A$2:$A$152,0))>=INDEX('Gamma Data'!$B$2:$B$152,MATCH(J32,'Gamma Data'!$A$2:$A$152,0))*1.5),"Put เด่น","(mixed)"))) | AB32: =IF(NOT(ISNUMBER('Gamma Data'!A32)),"",IF((ABS('Gamma Data'!B32)+ABS('Gamma Data'!C32))=0,"",IF(OR(ABS('Gamma Data'!A32-$J$6)>$J$6*$J$26,ABS('Gamma Data'!A32-$J$6)<$J$28),"",(ABS('Gamma Data'!B32)+ABS('Gamma Data'!C32))/MAX(ABS('Gamma Data'!A32-$J$6)/($J$6*0.005),1)+ROW()/1000000000)))
A33: =IF('Gamma Data'!A33="","",'Gamma Data'!A33) | B33: =IF(A33="","",'Gamma Data'!B33-'Gamma Data'!C33) | C33: =IF(A33="","",ABS('Gamma Data'!B33)+ABS('Gamma Data'!C33)) | D33: =IF(A33="","",IF(C33=0,"-",IF(AND('Gamma Data'!B33>0,'Gamma Data'!B33>='Gamma Data'!C33*1.5),"Call Wall",IF(AND('Gamma Data'!C33>0,'Gamma Data'!C33>='Gamma Data'!B33*1.5),"Put Wall","(mixed)")))) | E33: =IF(OR(A33="",$J$12=0),"",C33/$J$12) | F33: =IF(A33="","",IF(C33>=2*$J$12,"จุดหนืด",IF(C33<=0.5*$J$12,"air pocket",""))) | H33: =IF(AND(A33>=$J$6,'Gamma Data'!B33>0,'Gamma Data'!B33>='Gamma Data'!C33*1.5),'Gamma Data'!B33,0) | I33: 4 | J33: =IF(COUNT($AB$2:$AB$152)<4,"",INDEX('Gamma Data'!$A$2:$A$152,MATCH(LARGE($AB$2:$AB$152,4),$AB$2:$AB$152,0))) | K33: =IF(J33="","",ABS(INDEX('Gamma Data'!$B$2:$B$152,MATCH(J33,'Gamma Data'!$A$2:$A$152,0)))+ABS(INDEX('Gamma Data'!$C$2:$C$152,MATCH(J33,'Gamma Data'!$A$2:$A$152,0)))) | L33: =IF(J33="","",J33-$J$6) | M33: =IF(J33="","",IF(AND(INDEX('Gamma Data'!$B$2:$B$152,MATCH(J33,'Gamma Data'!$A$2:$A$152,0))>0,INDEX('Gamma Data'!$B$2:$B$152,MATCH(J33,'Gamma Data'!$A$2:$A$152,0))>=INDEX('Gamma Data'!$C$2:$C$152,MATCH(J33,'Gamma Data'!$A$2:$A$152,0))*1.5),"Call เด่น",IF(AND(INDEX('Gamma Data'!$C$2:$C$152,MATCH(J33,'Gamma Data'!$A$2:$A$152,0))>0,INDEX('Gamma Data'!$C$2:$C$152,MATCH(J33,'Gamma Data'!$A$2:$A$152,0))>=INDEX('Gamma Data'!$B$2:$B$152,MATCH(J33,'Gamma Data'!$A$2:$A$152,0))*1.5),"Put เด่น","(mixed)"))) | AB33: =IF(NOT(ISNUMBER('Gamma Data'!A33)),"",IF((ABS('Gamma Data'!B33)+ABS('Gamma Data'!C33))=0,"",IF(OR(ABS('Gamma Data'!A33-$J$6)>$J$6*$J$26,ABS('Gamma Data'!A33-$J$6)<$J$28),"",(ABS('Gamma Data'!B33)+ABS('Gamma Data'!C33))/MAX(ABS('Gamma Data'!A33-$J$6)/($J$6*0.005),1)+ROW()/1000000000)))
A34: =IF('Gamma Data'!A34="","",'Gamma Data'!A34) | B34: =IF(A34="","",'Gamma Data'!B34-'Gamma Data'!C34) | C34: =IF(A34="","",ABS('Gamma Data'!B34)+ABS('Gamma Data'!C34)) | D34: =IF(A34="","",IF(C34=0,"-",IF(AND('Gamma Data'!B34>0,'Gamma Data'!B34>='Gamma Data'!C34*1.5),"Call Wall",IF(AND('Gamma Data'!C34>0,'Gamma Data'!C34>='Gamma Data'!B34*1.5),"Put Wall","(mixed)")))) | E34: =IF(OR(A34="",$J$12=0),"",C34/$J$12) | F34: =IF(A34="","",IF(C34>=2*$J$12,"จุดหนืด",IF(C34<=0.5*$J$12,"air pocket",""))) | H34: =IF(AND(A34>=$J$6,'Gamma Data'!B34>0,'Gamma Data'!B34>='Gamma Data'!C34*1.5),'Gamma Data'!B34,0) | I34: 5 | J34: =IF(COUNT($AB$2:$AB$152)<5,"",INDEX('Gamma Data'!$A$2:$A$152,MATCH(LARGE($AB$2:$AB$152,5),$AB$2:$AB$152,0))) | K34: =IF(J34="","",ABS(INDEX('Gamma Data'!$B$2:$B$152,MATCH(J34,'Gamma Data'!$A$2:$A$152,0)))+ABS(INDEX('Gamma Data'!$C$2:$C$152,MATCH(J34,'Gamma Data'!$A$2:$A$152,0)))) | L34: =IF(J34="","",J34-$J$6) | M34: =IF(J34="","",IF(AND(INDEX('Gamma Data'!$B$2:$B$152,MATCH(J34,'Gamma Data'!$A$2:$A$152,0))>0,INDEX('Gamma Data'!$B$2:$B$152,MATCH(J34,'Gamma Data'!$A$2:$A$152,0))>=INDEX('Gamma Data'!$C$2:$C$152,MATCH(J34,'Gamma Data'!$A$2:$A$152,0))*1.5),"Call เด่น",IF(AND(INDEX('Gamma Data'!$C$2:$C$152,MATCH(J34,'Gamma Data'!$A$2:$A$152,0))>0,INDEX('Gamma Data'!$C$2:$C$152,MATCH(J34,'Gamma Data'!$A$2:$A$152,0))>=INDEX('Gamma Data'!$B$2:$B$152,MATCH(J34,'Gamma Data'!$A$2:$A$152,0))*1.5),"Put เด่น","(mixed)"))) | AB34: =IF(NOT(ISNUMBER('Gamma Data'!A34)),"",IF((ABS('Gamma Data'!B34)+ABS('Gamma Data'!C34))=0,"",IF(OR(ABS('Gamma Data'!A34-$J$6)>$J$6*$J$26,ABS('Gamma Data'!A34-$J$6)<$J$28),"",(ABS('Gamma Data'!B34)+ABS('Gamma Data'!C34))/MAX(ABS('Gamma Data'!A34-$J$6)/($J$6*0.005),1)+ROW()/1000000000)))
A35: =IF('Gamma Data'!A35="","",'Gamma Data'!A35) | B35: =IF(A35="","",'Gamma Data'!B35-'Gamma Data'!C35) | C35: =IF(A35="","",ABS('Gamma Data'!B35)+ABS('Gamma Data'!C35)) | D35: =IF(A35="","",IF(C35=0,"-",IF(AND('Gamma Data'!B35>0,'Gamma Data'!B35>='Gamma Data'!C35*1.5),"Call Wall",IF(AND('Gamma Data'!C35>0,'Gamma Data'!C35>='Gamma Data'!B35*1.5),"Put Wall","(mixed)")))) | E35: =IF(OR(A35="",$J$12=0),"",C35/$J$12) | F35: =IF(A35="","",IF(C35>=2*$J$12,"จุดหนืด",IF(C35<=0.5*$J$12,"air pocket",""))) | H35: =IF(AND(A35>=$J$6,'Gamma Data'!B35>0,'Gamma Data'!B35>='Gamma Data'!C35*1.5),'Gamma Data'!B35,0) | AB35: =IF(NOT(ISNUMBER('Gamma Data'!A35)),"",IF((ABS('Gamma Data'!B35)+ABS('Gamma Data'!C35))=0,"",IF(OR(ABS('Gamma Data'!A35-$J$6)>$J$6*$J$26,ABS('Gamma Data'!A35-$J$6)<$J$28),"",(ABS('Gamma Data'!B35)+ABS('Gamma Data'!C35))/MAX(ABS('Gamma Data'!A35-$J$6)/($J$6*0.005),1)+ROW()/1000000000)))
A36: =IF('Gamma Data'!A36="","",'Gamma Data'!A36) | B36: =IF(A36="","",'Gamma Data'!B36-'Gamma Data'!C36) | C36: =IF(A36="","",ABS('Gamma Data'!B36)+ABS('Gamma Data'!C36)) | D36: =IF(A36="","",IF(C36=0,"-",IF(AND('Gamma Data'!B36>0,'Gamma Data'!B36>='Gamma Data'!C36*1.5),"Call Wall",IF(AND('Gamma Data'!C36>0,'Gamma Data'!C36>='Gamma Data'!B36*1.5),"Put Wall","(mixed)")))) | E36: =IF(OR(A36="",$J$12=0),"",C36/$J$12) | F36: =IF(A36="","",IF(C36>=2*$J$12,"จุดหนืด",IF(C36<=0.5*$J$12,"air pocket",""))) | H36: =IF(AND(A36>=$J$6,'Gamma Data'!B36>0,'Gamma Data'!B36>='Gamma Data'!C36*1.5),'Gamma Data'!B36,0) | W36: =IF(NOT(ISNUMBER('Gamma Data'!A36)),"",IF((ABS('Gamma Data'!B36)+ABS('Gamma Data'!C36))=0,"",IF(ABS('Gamma Data'!A36-$J$6)>$J$6*$J$26,"",(ABS('Gamma Data'!B36)+ABS('Gamma Data'!C36))/MAX(ABS('Gamma Data'!A36-$J$6)/($J$6*0.005),1)+ROW()/1000000000))) | AB36: =IF(NOT(ISNUMBER('Gamma Data'!A36)),"",IF((ABS('Gamma Data'!B36)+ABS('Gamma Data'!C36))=0,"",IF(OR(ABS('Gamma Data'!A36-$J$6)>$J$6*$J$26,ABS('Gamma Data'!A36-$J$6)<$J$28),"",(ABS('Gamma Data'!B36)+ABS('Gamma Data'!C36))/MAX(ABS('Gamma Data'!A36-$J$6)/($J$6*0.005),1)+ROW()/1000000000)))
A37: =IF('Gamma Data'!A37="","",'Gamma Data'!A37) | B37: =IF(A37="","",'Gamma Data'!B37-'Gamma Data'!C37) | C37: =IF(A37="","",ABS('Gamma Data'!B37)+ABS('Gamma Data'!C37)) | D37: =IF(A37="","",IF(C37=0,"-",IF(AND('Gamma Data'!B37>0,'Gamma Data'!B37>='Gamma Data'!C37*1.5),"Call Wall",IF(AND('Gamma Data'!C37>0,'Gamma Data'!C37>='Gamma Data'!B37*1.5),"Put Wall","(mixed)")))) | E37: =IF(OR(A37="",$J$12=0),"",C37/$J$12) | F37: =IF(A37="","",IF(C37>=2*$J$12,"จุดหนืด",IF(C37<=0.5*$J$12,"air pocket",""))) | H37: =IF(AND(A37>=$J$6,'Gamma Data'!B37>0,'Gamma Data'!B37>='Gamma Data'!C37*1.5),'Gamma Data'!B37,0) | W37: =IF(NOT(ISNUMBER('Gamma Data'!A37)),"",IF((ABS('Gamma Data'!B37)+ABS('Gamma Data'!C37))=0,"",IF(ABS('Gamma Data'!A37-$J$6)>$J$6*$J$26,"",(ABS('Gamma Data'!B37)+ABS('Gamma Data'!C37))/MAX(ABS('Gamma Data'!A37-$J$6)/($J$6*0.005),1)+ROW()/1000000000))) | AB37: =IF(NOT(ISNUMBER('Gamma Data'!A37)),"",IF((ABS('Gamma Data'!B37)+ABS('Gamma Data'!C37))=0,"",IF(OR(ABS('Gamma Data'!A37-$J$6)>$J$6*$J$26,ABS('Gamma Data'!A37-$J$6)<$J$28),"",(ABS('Gamma Data'!B37)+ABS('Gamma Data'!C37))/MAX(ABS('Gamma Data'!A37-$J$6)/($J$6*0.005),1)+ROW()/1000000000)))
A38: =IF('Gamma Data'!A38="","",'Gamma Data'!A38) | B38: =IF(A38="","",'Gamma Data'!B38-'Gamma Data'!C38) | C38: =IF(A38="","",ABS('Gamma Data'!B38)+ABS('Gamma Data'!C38)) | D38: =IF(A38="","",IF(C38=0,"-",IF(AND('Gamma Data'!B38>0,'Gamma Data'!B38>='Gamma Data'!C38*1.5),"Call Wall",IF(AND('Gamma Data'!C38>0,'Gamma Data'!C38>='Gamma Data'!B38*1.5),"Put Wall","(mixed)")))) | E38: =IF(OR(A38="",$J$12=0),"",C38/$J$12) | F38: =IF(A38="","",IF(C38>=2*$J$12,"จุดหนืด",IF(C38<=0.5*$J$12,"air pocket",""))) | H38: =IF(AND(A38>=$J$6,'Gamma Data'!B38>0,'Gamma Data'!B38>='Gamma Data'!C38*1.5),'Gamma Data'!B38,0) | W38: =IF(NOT(ISNUMBER('Gamma Data'!A38)),"",IF((ABS('Gamma Data'!B38)+ABS('Gamma Data'!C38))=0,"",IF(ABS('Gamma Data'!A38-$J$6)>$J$6*$J$26,"",(ABS('Gamma Data'!B38)+ABS('Gamma Data'!C38))/MAX(ABS('Gamma Data'!A38-$J$6)/($J$6*0.005),1)+ROW()/1000000000))) | AB38: =IF(NOT(ISNUMBER('Gamma Data'!A38)),"",IF((ABS('Gamma Data'!B38)+ABS('Gamma Data'!C38))=0,"",IF(OR(ABS('Gamma Data'!A38-$J$6)>$J$6*$J$26,ABS('Gamma Data'!A38-$J$6)<$J$28),"",(ABS('Gamma Data'!B38)+ABS('Gamma Data'!C38))/MAX(ABS('Gamma Data'!A38-$J$6)/($J$6*0.005),1)+ROW()/1000000000)))
A39: =IF('Gamma Data'!A39="","",'Gamma Data'!A39) | B39: =IF(A39="","",'Gamma Data'!B39-'Gamma Data'!C39) | C39: =IF(A39="","",ABS('Gamma Data'!B39)+ABS('Gamma Data'!C39)) | D39: =IF(A39="","",IF(C39=0,"-",IF(AND('Gamma Data'!B39>0,'Gamma Data'!B39>='Gamma Data'!C39*1.5),"Call Wall",IF(AND('Gamma Data'!C39>0,'Gamma Data'!C39>='Gamma Data'!B39*1.5),"Put Wall","(mixed)")))) | E39: =IF(OR(A39="",$J$12=0),"",C39/$J$12) | F39: =IF(A39="","",IF(C39>=2*$J$12,"จุดหนืด",IF(C39<=0.5*$J$12,"air pocket",""))) | H39: =IF(AND(A39>=$J$6,'Gamma Data'!B39>0,'Gamma Data'!B39>='Gamma Data'!C39*1.5),'Gamma Data'!B39,0) | W39: =IF(NOT(ISNUMBER('Gamma Data'!A39)),"",IF((ABS('Gamma Data'!B39)+ABS('Gamma Data'!C39))=0,"",IF(ABS('Gamma Data'!A39-$J$6)>$J$6*$J$26,"",(ABS('Gamma Data'!B39)+ABS('Gamma Data'!C39))/MAX(ABS('Gamma Data'!A39-$J$6)/($J$6*0.005),1)+ROW()/1000000000))) | AB39: =IF(NOT(ISNUMBER('Gamma Data'!A39)),"",IF((ABS('Gamma Data'!B39)+ABS('Gamma Data'!C39))=0,"",IF(OR(ABS('Gamma Data'!A39-$J$6)>$J$6*$J$26,ABS('Gamma Data'!A39-$J$6)<$J$28),"",(ABS('Gamma Data'!B39)+ABS('Gamma Data'!C39))/MAX(ABS('Gamma Data'!A39-$J$6)/($J$6*0.005),1)+ROW()/1000000000)))
A40: =IF('Gamma Data'!A40="","",'Gamma Data'!A40) | B40: =IF(A40="","",'Gamma Data'!B40-'Gamma Data'!C40) | C40: =IF(A40="","",ABS('Gamma Data'!B40)+ABS('Gamma Data'!C40)) | D40: =IF(A40="","",IF(C40=0,"-",IF(AND('Gamma Data'!B40>0,'Gamma Data'!B40>='Gamma Data'!C40*1.5),"Call Wall",IF(AND('Gamma Data'!C40>0,'Gamma Data'!C40>='Gamma Data'!B40*1.5),"Put Wall","(mixed)")))) | E40: =IF(OR(A40="",$J$12=0),"",C40/$J$12) | F40: =IF(A40="","",IF(C40>=2*$J$12,"จุดหนืด",IF(C40<=0.5*$J$12,"air pocket",""))) | H40: =IF(AND(A40>=$J$6,'Gamma Data'!B40>0,'Gamma Data'!B40>='Gamma Data'!C40*1.5),'Gamma Data'!B40,0) | W40: =IF(NOT(ISNUMBER('Gamma Data'!A40)),"",IF((ABS('Gamma Data'!B40)+ABS('Gamma Data'!C40))=0,"",IF(ABS('Gamma Data'!A40-$J$6)>$J$6*$J$26,"",(ABS('Gamma Data'!B40)+ABS('Gamma Data'!C40))/MAX(ABS('Gamma Data'!A40-$J$6)/($J$6*0.005),1)+ROW()/1000000000))) | AB40: =IF(NOT(ISNUMBER('Gamma Data'!A40)),"",IF((ABS('Gamma Data'!B40)+ABS('Gamma Data'!C40))=0,"",IF(OR(ABS('Gamma Data'!A40-$J$6)>$J$6*$J$26,ABS('Gamma Data'!A40-$J$6)<$J$28),"",(ABS('Gamma Data'!B40)+ABS('Gamma Data'!C40))/MAX(ABS('Gamma Data'!A40-$J$6)/($J$6*0.005),1)+ROW()/1000000000)))
...

Sheet บันทึกโหมด
A1: วันที่ | B1: โหมด GEX | C1: ทิศทั้งวัน | D1: ทิศ 30 นาทีสุดท้าย | E1: ไปทางเดียวกัน? | F1: หมายเหตุ | H1: ── โหมดวันนี้ (จาก Gamma Data) ──
E2: =IF(OR(B2="",C2="",D2=""),"",IF(C2=D2,"ใช่","ไม่")) | H2: โหมด GEX | I2: =IF(I3="","",IF(I3<0.05,"สมดุล",IF((SUM('Gamma Data'!$B$2:$B$152)-SUM('Gamma Data'!$C$2:$C$152))>0,"บวก","ลบ")))
E3: =IF(OR(B3="",C3="",D3=""),"",IF(C3=D3,"ใช่","ไม่")) | H3: Conviction | I3: =IF(SUMPRODUCT(ABS('Gamma Data'!$B$2:$B$152-'Gamma Data'!$C$2:$C$152))=0,"",ABS((SUM('Gamma Data'!$B$2:$B$152)-SUM('Gamma Data'!$C$2:$C$152)))/SUMPRODUCT(ABS('Gamma Data'!$B$2:$B$152-'Gamma Data'!$C$2:$C$152)))
E4: =IF(OR(B4="",C4="",D4=""),"",IF(C4=D4,"ใช่","ไม่"))
E5: =IF(OR(B5="",C5="",D5=""),"",IF(C5=D5,"ใช่","ไม่")) | H5: ── ผลสะสม ──
E6: =IF(OR(B6="",C6="",D6=""),"",IF(C6=D6,"ใช่","ไม่")) | H6: โหมด | I6: จำนวนวัน | J6: ไปทางเดียวกัน | K6: % ไปทางเดียวกัน
E7: =IF(OR(B7="",C7="",D7=""),"",IF(C7=D7,"ใช่","ไม่")) | H7: บวก | I7: =COUNTIFS($B$2:$B$401,H7,$E$2:$E$401,"?*") | J7: =COUNTIFS($B$2:$B$401,H7,$E$2:$E$401,"ใช่") | K7: =IF(I7=0,"",J7/I7)
E8: =IF(OR(B8="",C8="",D8=""),"",IF(C8=D8,"ใช่","ไม่")) | H8: ลบ | I8: =COUNTIFS($B$2:$B$401,H8,$E$2:$E$401,"?*") | J8: =COUNTIFS($B$2:$B$401,H8,$E$2:$E$401,"ใช่") | K8: =IF(I8=0,"",J8/I8)
E9: =IF(OR(B9="",C9="",D9=""),"",IF(C9=D9,"ใช่","ไม่")) | H9: สมดุล | I9: =COUNTIFS($B$2:$B$401,H9,$E$2:$E$401,"?*") | J9: =COUNTIFS($B$2:$B$401,H9,$E$2:$E$401,"ใช่") | K9: =IF(I9=0,"",J9/I9)
E10: =IF(OR(B10="",C10="",D10=""),"",IF(C10=D10,"ใช่","ไม่")) | H10: รวม | I10: =SUM(I7:I9) | J10: =SUM(J7:J9) | K10: =IF(I10=0,"",J10/I10)
E11: =IF(OR(B11="",C11="",D11=""),"",IF(C11=D11,"ใช่","ไม่"))
E12: =IF(OR(B12="",C12="",D12=""),"",IF(C12=D12,"ใช่","ไม่")) | H12: ลบ − บวก | I12: =IF(OR(K7="",K8=""),"",K8-K7)
E13: =IF(OR(B13="",C13="",D13=""),"",IF(C13=D13,"ใช่","ไม่")) | H13: ค่า z | I13: =IF(OR(I7<30,I8<30),"",IF(SQRT(((J7+J8)/(I7+I8))*(1-((J7+J8)/(I7+I8)))*(1/I7+1/I8))=0,"",(K8-K7)/SQRT(((J7+J8)/(I7+I8))*(1-((J7+J8)/(I7+I8)))*(1/I7+1/I8))))
E14: =IF(OR(B14="",C14="",D14=""),"",IF(C14=D14,"ใช่","ไม่")) | H14: อ่านผล | I14: =IF(OR(I7<30,I8<30),"ข้อมูลยังน้อย - ต้องมีโหมดละ 30 วัน (บวก "&I7&" / ลบ "&I8&")",IF(I13="","",IF(I13>=1.96,"โหมดลบไปทางเดียวกันบ่อยกว่าชัดเจน - ตรงกับ Baltussen",IF(I13<=-1.96,"กลับด้านกับ Baltussen - โหมดบวกไปทางเดียวกันบ่อยกว่า","ยังแยกจากความบังเอิญไม่ได้"))))
E15: =IF(OR(B15="",C15="",D15=""),"",IF(C15=D15,"ใช่","ไม่"))
E16: =IF(OR(B16="",C16="",D16=""),"",IF(C16=D16,"ใช่","ไม่")) | H16: วิธีกรอก: วันละ 1 แถว เลือกช่องเหลือง B-D จาก dropdown · โหมด = ค่าที่ช่อง I2 จากข้อมูล GEX ที่มีตอนก่อนเทรดวันนั้น · ทิศทั้งวัน = จากราคา settlement เมื่อวาน ถึง 30 นาทีก่อน settlement วันนี้ · 30 นาทีสุดท้าย = 13:00-13:30 เวลานิวยอร์ก (ราว 00:00-00:30 น. เวลาไทยช่วง DST / 01:00-01:30 น. ช่วงหน้าหนาว) · วันที่ราคาแทบไม่ขยับให้เว้นแถว · ถ้าไม่มีผลอะไร ทุกโหมดควรได้ราว 50% · ที่มา: Baltussen et al. พบในทองคำ (GC) ว่าราคาทั้งวันทำนายทิศ 30 นาทีสุดท้ายได้ และใน S&P พบโมเมนตัมเฉพาะวัน gamma ลบ · เกณฑ์: z 1.96 = ความเชื่อมั่น 95% แบบสองทาง (มาตรฐานสถิติ) · 30 วันต่อโหมด = กฎทั่วไป · conviction 5% = เกณฑ์เดิมของไฟล์ (ตั้งเอง)
E17: =IF(OR(B17="",C17="",D17=""),"",IF(C17=D17,"ใช่","ไม่"))
E18: =IF(OR(B18="",C18="",D18=""),"",IF(C18=D18,"ใช่","ไม่"))
E19: =IF(OR(B19="",C19="",D19=""),"",IF(C19=D19,"ใช่","ไม่"))
E20: =IF(OR(B20="",C20="",D20=""),"",IF(C20=D20,"ใช่","ไม่"))
E21: =IF(OR(B21="",C21="",D21=""),"",IF(C21=D21,"ใช่","ไม่"))
E22: =IF(OR(B22="",C22="",D22=""),"",IF(C22=D22,"ใช่","ไม่"))
E23: =IF(OR(B23="",C23="",D23=""),"",IF(C23=D23,"ใช่","ไม่"))
E24: =IF(OR(B24="",C24="",D24=""),"",IF(C24=D24,"ใช่","ไม่"))
E25: =IF(OR(B25="",C25="",D25=""),"",IF(C25=D25,"ใช่","ไม่"))
E26: =IF(OR(B26="",C26="",D26=""),"",IF(C26=D26,"ใช่","ไม่"))
E27: =IF(OR(B27="",C27="",D27=""),"",IF(C27=D27,"ใช่","ไม่"))
E28: =IF(OR(B28="",C28="",D28=""),"",IF(C28=D28,"ใช่","ไม่"))
... E401: =IF(OR(B401="",C401="",D401=""),"",IF(C401=D401,"ใช่","ไม่"))

Sheet Log
A1: วันที่ข้อมูล | B1: สัญญา | C1: ราคา | D1: รวม Call Gamma | E1: รวม Put Gamma | F1: NET GEX | G1: สถานะ | H1: Gamma Flip (ใกล้ราคา) | I1: Strike gamma สูงสุด | J1: บันทึกเมื่อ
A2: 46294 | B2: G1RV6 | C2: 4179.7 | D2: 164 | E2: 351 | F2: -187 | G2: Negative GEX (แกว่งแรง) | I2: 4200 | J2: 46296.376
A3: 46295 | B3: G1RV6 | C3: 4186.7 | D3: 314 | E3: 471 | F3: -157 | G3: Negative GEX (แกว่งแรง) | I3: 4200 | J3: 46296.618
A4: 46295 | B4: OG1V6 | C4: 4186.7 | D4: 232 | E4: 595 | F4: -363 | G4: Negative GEX (แกว่งแรง) | I4: 4200 | J4: 46297.41
A5: 46297 | B5: G1MV6 | C5: 4162.3 | D5: 281 | E5: 339 | F5: -58 | G5: Negative GEX (แกว่งแรง) | I5: 4170 | J5: 46300.379
A6: 46297 | B6: G1TV6 | C6: 4162.3 | D6: 153 | E6: 209 | F6: -56 | G6: Negative GEX (แกว่งแรง) | I6: 4175 | J6: 46301.385
A7: 46301 | B7: G1WV6 | C7: 4158.9 | D7: 317 | E7: 327 | F7: -10 | G7: Negative GEX (แกว่งแรง) | I7: 4185 | J7: 46302.586
