Workbook

Sheet OI Data
A1: STRIKE | B1: CALL OI | C1: PUT OI | E1: ข้อมูลกำกับชุดนี้ (กรอกทุกครั้ง)
A2: 3750 | B2: 0 | C2: 10 | E2: Expiration code | F2: MW1 Week 4 - SEP 2026 (U26) | G2: เช่น G5MQ6 - ห้ามปนสัญญาเด็ดขาด
A3: 3800 | B3: 0 | C3: 12 | E3: วันที่ของข้อมูล | F3: 46290 | G3: วัน settlement ที่ดึงมา
A4: 3900 | B4: 0 | C4: 20 | E4: DTE เหลือกี่วัน | F4: 3 | G4: เกิน 7 วัน = ไม่มีสัญญาณตามงานวิจัย
A5: 3925 | B5: 0 | C5: 2 | E5: Call OI รวม จากหน้า CME | F5: 3432 | G5: ตัวเลข call oi ที่หน้า OI Chart โชว์
A6: 3955 | B6: 0 | C6: 1 | E6: Put OI รวม จากหน้า CME | F6: 3798 | G6: ตัวเลข put oi ที่หน้า OI Chart โชว์
A7: 3960 | B7: 0 | C7: 5
A8: 3975 | B8: 0 | C8: 3
A9: 4000 | B9: 1 | C9: 135
A10: 4025 | B10: 0 | C10: 24
A11: 4040 | B11: 0 | C11: 1
A12: 4045 | B12: 0 | C12: 1
A13: 4050 | B13: 0 | C13: 6
A14: 4060 | B14: 0 | C14: 1
A15: 4075 | B15: 0 | C15: 55
A16: 4080 | B16: 0 | C16: 61
A17: 4085 | B17: 0 | C17: 54
A18: 4090 | B18: 0 | C18: 1
... A134: 5400 | B134: 17 | C134: 0
A203: expiration เดียว วันเดียวเท่านั้น | สูตรครอบคลุมแถว 2-201 (200 strike) ช่อง "ตรวจช่วงสูตร" ในชีท Max Pain Calc จะเตือนเองถ้ากรอกเกินช่วงนี้

Sheet Max Pain Calc
A1: STRIKE | B1: PAIN รวม | C1: P/C OI Ratio | E1: ผลการคำนวณ
A2: =IF('OI Data'!A2="","",'OI Data'!A2) | B2: =IF($A2="","",SUMPRODUCT(('OI Data'!$A$2:$A$201<$A2)*($A2-'OI Data'!$A$2:$A$201)*'OI Data'!$B$2:$B$201)+SUMPRODUCT(('OI Data'!$A$2:$A$201>$A2)*('OI Data'!$A$2:$A$201-$A2)*'OI Data'!$C$2:$C$201)) | C2: =IF($A2="","",IF('OI Data'!B2=0,IF('OI Data'!C2=0,"-","Put ล้วน"),'OI Data'!C2/'OI Data'!B2)) | E2: MAX PAIN STRIKE | F2: =INDEX($A$2:$A$201,MATCH(MIN($B$2:$B$201),$B$2:$B$201,0))
A3: =IF('OI Data'!A3="","",'OI Data'!A3) | B3: =IF($A3="","",SUMPRODUCT(('OI Data'!$A$2:$A$201<$A3)*($A3-'OI Data'!$A$2:$A$201)*'OI Data'!$B$2:$B$201)+SUMPRODUCT(('OI Data'!$A$2:$A$201>$A3)*('OI Data'!$A$2:$A$201-$A3)*'OI Data'!$C$2:$C$201)) | C3: =IF($A3="","",IF('OI Data'!B3=0,IF('OI Data'!C3=0,"-","Put ล้วน"),'OI Data'!C3/'OI Data'!B3)) | E3: PAIN ต่ำสุด | F3: =MIN($B$2:$B$201)
A4: =IF('OI Data'!A4="","",'OI Data'!A4) | B4: =IF($A4="","",SUMPRODUCT(('OI Data'!$A$2:$A$201<$A4)*($A4-'OI Data'!$A$2:$A$201)*'OI Data'!$B$2:$B$201)+SUMPRODUCT(('OI Data'!$A$2:$A$201>$A4)*('OI Data'!$A$2:$A$201-$A4)*'OI Data'!$C$2:$C$201)) | C4: =IF($A4="","",IF('OI Data'!B4=0,IF('OI Data'!C4=0,"-","Put ล้วน"),'OI Data'!C4/'OI Data'!B4)) | E4: ราคาปัจจุบัน (กรอกเอง) | F4: 4321.2
A5: =IF('OI Data'!A5="","",'OI Data'!A5) | B5: =IF($A5="","",SUMPRODUCT(('OI Data'!$A$2:$A$201<$A5)*($A5-'OI Data'!$A$2:$A$201)*'OI Data'!$B$2:$B$201)+SUMPRODUCT(('OI Data'!$A$2:$A$201>$A5)*('OI Data'!$A$2:$A$201-$A5)*'OI Data'!$C$2:$C$201)) | C5: =IF($A5="","",IF('OI Data'!B5=0,IF('OI Data'!C5=0,"-","Put ล้วน"),'OI Data'!C5/'OI Data'!B5)) | E5: ตรวจช่วงสูตร | F5: =IF(COUNT('OI Data'!A:A)>F24,"เตือน: มีข้อมูล "&COUNT('OI Data'!A:A)&" แถว แต่สูตรครอบคลุม "&F24&" แถว - ต้องขยายช่วงสูตรก่อนใช้ผล","ช่วงสูตรครอบคลุมข้อมูลครบ "&F24&" แถว")
A6: =IF('OI Data'!A6="","",'OI Data'!A6) | B6: =IF($A6="","",SUMPRODUCT(('OI Data'!$A$2:$A$201<$A6)*($A6-'OI Data'!$A$2:$A$201)*'OI Data'!$B$2:$B$201)+SUMPRODUCT(('OI Data'!$A$2:$A$201>$A6)*('OI Data'!$A$2:$A$201-$A6)*'OI Data'!$C$2:$C$201)) | C6: =IF($A6="","",IF('OI Data'!B6=0,IF('OI Data'!C6=0,"-","Put ล้วน"),'OI Data'!C6/'OI Data'!B6)) | E6: เกณฑ์ที่ 1 — ระยะห่างเป็น %
A7: =IF('OI Data'!A7="","",'OI Data'!A7) | B7: =IF($A7="","",SUMPRODUCT(('OI Data'!$A$2:$A$201<$A7)*($A7-'OI Data'!$A$2:$A$201)*'OI Data'!$B$2:$B$201)+SUMPRODUCT(('OI Data'!$A$2:$A$201>$A7)*('OI Data'!$A$2:$A$201-$A7)*'OI Data'!$C$2:$C$201)) | C7: =IF($A7="","",IF('OI Data'!B7=0,IF('OI Data'!C7=0,"-","Put ล้วน"),'OI Data'!C7/'OI Data'!B7)) | E7: ห่างจากราคา (จุด) | F7: =F2-F4
A8: =IF('OI Data'!A8="","",'OI Data'!A8) | B8: =IF($A8="","",SUMPRODUCT(('OI Data'!$A$2:$A$201<$A8)*($A8-'OI Data'!$A$2:$A$201)*'OI Data'!$B$2:$B$201)+SUMPRODUCT(('OI Data'!$A$2:$A$201>$A8)*('OI Data'!$A$2:$A$201-$A8)*'OI Data'!$C$2:$C$201)) | C8: =IF($A8="","",IF('OI Data'!B8=0,IF('OI Data'!C8=0,"-","Put ล้วน"),'OI Data'!C8/'OI Data'!B8)) | E8: Max Pain measure (%) | F8: =IF(F4=0,"",(F2-F4)/F4)
A9: =IF('OI Data'!A9="","",'OI Data'!A9) | B9: =IF($A9="","",SUMPRODUCT(('OI Data'!$A$2:$A$201<$A9)*($A9-'OI Data'!$A$2:$A$201)*'OI Data'!$B$2:$B$201)+SUMPRODUCT(('OI Data'!$A$2:$A$201>$A9)*('OI Data'!$A$2:$A$201-$A9)*'OI Data'!$C$2:$C$201)) | C9: =IF($A9="","",IF('OI Data'!B9=0,IF('OI Data'!C9=0,"-","Put ล้วน"),'OI Data'!C9/'OI Data'!B9)) | E9: เกณฑ์โซนกลาง (แก้เองได้) | F9: 0.02
A10: =IF('OI Data'!A10="","",'OI Data'!A10) | B10: =IF($A10="","",SUMPRODUCT(('OI Data'!$A$2:$A$201<$A10)*($A10-'OI Data'!$A$2:$A$201)*'OI Data'!$B$2:$B$201)+SUMPRODUCT(('OI Data'!$A$2:$A$201>$A10)*('OI Data'!$A$2:$A$201-$A10)*'OI Data'!$C$2:$C$201)) | C10: =IF($A10="","",IF('OI Data'!B10=0,IF('OI Data'!C10=0,"-","Put ล้วน"),'OI Data'!C10/'OI Data'!B10)) | E10: เกณฑ์โซนมีผล (แก้เองได้) | F10: 0.05
A11: =IF('OI Data'!A11="","",'OI Data'!A11) | B11: =IF($A11="","",SUMPRODUCT(('OI Data'!$A$2:$A$201<$A11)*($A11-'OI Data'!$A$2:$A$201)*'OI Data'!$B$2:$B$201)+SUMPRODUCT(('OI Data'!$A$2:$A$201>$A11)*('OI Data'!$A$2:$A$201-$A11)*'OI Data'!$C$2:$C$201)) | C11: =IF($A11="","",IF('OI Data'!B11=0,IF('OI Data'!C11=0,"-","Put ล้วน"),'OI Data'!C11/'OI Data'!B11)) | E11: เทียบกับงานวิจัย | F11: =IF(F8="","",IF(ABS(F8)<F9,"โซนกลาง - ไม่มี edge ตามงานวิจัย",IF(ABS(F8)<F10,"เริ่มออกจากโซนกลาง แต่ยังไม่ถึงกลุ่มที่ทำกำไร",IF(F8>0,"เข้าโซนแบบ P10 (ทิศทางที่แข็งแรงกว่า)","เข้าโซนแบบ P1 (ทิศทางที่อ่อนกว่า)"))))
A12: =IF('OI Data'!A12="","",'OI Data'!A12) | B12: =IF($A12="","",SUMPRODUCT(('OI Data'!$A$2:$A$201<$A12)*($A12-'OI Data'!$A$2:$A$201)*'OI Data'!$B$2:$B$201)+SUMPRODUCT(('OI Data'!$A$2:$A$201>$A12)*('OI Data'!$A$2:$A$201-$A12)*'OI Data'!$C$2:$C$201)) | C12: =IF($A12="","",IF('OI Data'!B12=0,IF('OI Data'!C12=0,"-","Put ล้วน"),'OI Data'!C12/'OI Data'!B12)) | E12: ทิศทาง | F12: =IF(F8="","",IF(F8>0,"ฝั่งที่งานวิจัยพบผลแรงกว่า"," ฝั่งที่ผลอ่อนกว่ามาก"))
A13: =IF('OI Data'!A13="","",'OI Data'!A13) | B13: =IF($A13="","",SUMPRODUCT(('OI Data'!$A$2:$A$201<$A13)*($A13-'OI Data'!$A$2:$A$201)*'OI Data'!$B$2:$B$201)+SUMPRODUCT(('OI Data'!$A$2:$A$201>$A13)*('OI Data'!$A$2:$A$201-$A13)*'OI Data'!$C$2:$C$201)) | C13: =IF($A13="","",IF('OI Data'!B13=0,IF('OI Data'!C13=0,"-","Put ล้วน"),'OI Data'!C13/'OI Data'!B13))
A14: =IF('OI Data'!A14="","",'OI Data'!A14) | B14: =IF($A14="","",SUMPRODUCT(('OI Data'!$A$2:$A$201<$A14)*($A14-'OI Data'!$A$2:$A$201)*'OI Data'!$B$2:$B$201)+SUMPRODUCT(('OI Data'!$A$2:$A$201>$A14)*('OI Data'!$A$2:$A$201-$A14)*'OI Data'!$C$2:$C$201)) | C14: =IF($A14="","",IF('OI Data'!B14=0,IF('OI Data'!C14=0,"-","Put ล้วน"),'OI Data'!C14/'OI Data'!B14)) | E14: เกณฑ์ที่ 2 — ความชัดของก้นหุบ
A15: =IF('OI Data'!A15="","",'OI Data'!A15) | B15: =IF($A15="","",SUMPRODUCT(('OI Data'!$A$2:$A$201<$A15)*($A15-'OI Data'!$A$2:$A$201)*'OI Data'!$B$2:$B$201)+SUMPRODUCT(('OI Data'!$A$2:$A$201>$A15)*('OI Data'!$A$2:$A$201-$A15)*'OI Data'!$C$2:$C$201)) | C15: =IF($A15="","",IF('OI Data'!B15=0,IF('OI Data'!C15=0,"-","Put ล้วน"),'OI Data'!C15/'OI Data'!B15)) | E15: จำนวน strike ที่ pain ต่างจากต่ำสุด <2% | F15: =COUNTIF($B$2:$B$201,"<"&F3*1.02)
A16: =IF('OI Data'!A16="","",'OI Data'!A16) | B16: =IF($A16="","",SUMPRODUCT(('OI Data'!$A$2:$A$201<$A16)*($A16-'OI Data'!$A$2:$A$201)*'OI Data'!$B$2:$B$201)+SUMPRODUCT(('OI Data'!$A$2:$A$201>$A16)*('OI Data'!$A$2:$A$201-$A16)*'OI Data'!$C$2:$C$201)) | C16: =IF($A16="","",IF('OI Data'!B16=0,IF('OI Data'!C16=0,"-","Put ล้วน"),'OI Data'!C16/'OI Data'!B16)) | E16: ช่วงราคาของก้นหุบ | F16: =IF(F15=0,"",INDEX($A$2:$A$201,MATCH(TRUE(),INDEX($B$2:$B$201<F3*1.02,0),0))&" - "&LOOKUP(2,1/($B$2:$B$201<F3*1.02),$A$2:$A$201))
A17: =IF('OI Data'!A17="","",'OI Data'!A17) | B17: =IF($A17="","",SUMPRODUCT(('OI Data'!$A$2:$A$201<$A17)*($A17-'OI Data'!$A$2:$A$201)*'OI Data'!$B$2:$B$201)+SUMPRODUCT(('OI Data'!$A$2:$A$201>$A17)*('OI Data'!$A$2:$A$201-$A17)*'OI Data'!$C$2:$C$201)) | C17: =IF($A17="","",IF('OI Data'!B17=0,IF('OI Data'!C17=0,"-","Put ล้วน"),'OI Data'!C17/'OI Data'!B17)) | E17: อ่านว่า | F17: =IF(F15="","",IF(F15>=5,"ก้นหุบแบนมาก - ใช้เป็นโซนเท่านั้น",IF(F15>=3,"ก้นหุบค่อนข้างแบน - มองเป็นโซนดีกว่าจุดเดียว","ก้นหุบชัด - จุดที่ได้มีความหมาย")))
A18: =IF('OI Data'!A18="","",'OI Data'!A18) | B18: =IF($A18="","",SUMPRODUCT(('OI Data'!$A$2:$A$201<$A18)*($A18-'OI Data'!$A$2:$A$201)*'OI Data'!$B$2:$B$201)+SUMPRODUCT(('OI Data'!$A$2:$A$201>$A18)*('OI Data'!$A$2:$A$201-$A18)*'OI Data'!$C$2:$C$201)) | C18: =IF($A18="","",IF('OI Data'!B18=0,IF('OI Data'!C18=0,"-","Put ล้วน"),'OI Data'!C18/'OI Data'!B18))
A19: =IF('OI Data'!A19="","",'OI Data'!A19) | B19: =IF($A19="","",SUMPRODUCT(('OI Data'!$A$2:$A$201<$A19)*($A19-'OI Data'!$A$2:$A$201)*'OI Data'!$B$2:$B$201)+SUMPRODUCT(('OI Data'!$A$2:$A$201>$A19)*('OI Data'!$A$2:$A$201-$A19)*'OI Data'!$C$2:$C$201)) | C19: =IF($A19="","",IF('OI Data'!B19=0,IF('OI Data'!C19=0,"-","Put ล้วน"),'OI Data'!C19/'OI Data'!B19)) | E19: เกณฑ์ที่ 3 — ความสอดคล้อง P/C Ratio
A20: =IF('OI Data'!A20="","",'OI Data'!A20) | B20: =IF($A20="","",SUMPRODUCT(('OI Data'!$A$2:$A$201<$A20)*($A20-'OI Data'!$A$2:$A$201)*'OI Data'!$B$2:$B$201)+SUMPRODUCT(('OI Data'!$A$2:$A$201>$A20)*('OI Data'!$A$2:$A$201-$A20)*'OI Data'!$C$2:$C$201)) | C20: =IF($A20="","",IF('OI Data'!B20=0,IF('OI Data'!C20=0,"-","Put ล้วน"),'OI Data'!C20/'OI Data'!B20)) | E20: Put OI ÷ Call OI รวม | F20: =IF(SUM('OI Data'!$B$2:$B$201)=0,"",SUM('OI Data'!$C$2:$C$201)/SUM('OI Data'!$B$2:$B$201))
A21: =IF('OI Data'!A21="","",'OI Data'!A21) | B21: =IF($A21="","",SUMPRODUCT(('OI Data'!$A$2:$A$201<$A21)*($A21-'OI Data'!$A$2:$A$201)*'OI Data'!$B$2:$B$201)+SUMPRODUCT(('OI Data'!$A$2:$A$201>$A21)*('OI Data'!$A$2:$A$201-$A21)*'OI Data'!$C$2:$C$201)) | C21: =IF($A21="","",IF('OI Data'!B21=0,IF('OI Data'!C21=0,"-","Put ล้วน"),'OI Data'!C21/'OI Data'!B21)) | E21: สอดคล้องกันไหม | F21: =IF(OR(F8="",F20=""),"",IF(ABS(F8)<F9,"ไม่ประเมิน (อยู่โซนกลาง P/C ควรใกล้ 1 อยู่แล้ว)",IF(OR(AND(F8>0,F20>1),AND(F8<0,F20<1)),"สอดคล้อง","ขัดแย้ง - ตรวจข้อมูลอีกครั้ง")))
A22: =IF('OI Data'!A22="","",'OI Data'!A22) | B22: =IF($A22="","",SUMPRODUCT(('OI Data'!$A$2:$A$201<$A22)*($A22-'OI Data'!$A$2:$A$201)*'OI Data'!$B$2:$B$201)+SUMPRODUCT(('OI Data'!$A$2:$A$201>$A22)*('OI Data'!$A$2:$A$201-$A22)*'OI Data'!$C$2:$C$201)) | C22: =IF($A22="","",IF('OI Data'!B22=0,IF('OI Data'!C22=0,"-","Put ล้วน"),'OI Data'!C22/'OI Data'!B22))
A23: =IF('OI Data'!A23="","",'OI Data'!A23) | B23: =IF($A23="","",SUMPRODUCT(('OI Data'!$A$2:$A$201<$A23)*($A23-'OI Data'!$A$2:$A$201)*'OI Data'!$B$2:$B$201)+SUMPRODUCT(('OI Data'!$A$2:$A$201>$A23)*('OI Data'!$A$2:$A$201-$A23)*'OI Data'!$C$2:$C$201)) | C23: =IF($A23="","",IF('OI Data'!B23=0,IF('OI Data'!C23=0,"-","Put ล้วน"),'OI Data'!C23/'OI Data'!B23)) | E23: ความครอบคลุมของข้อมูล
A24: =IF('OI Data'!A24="","",'OI Data'!A24) | B24: =IF($A24="","",SUMPRODUCT(('OI Data'!$A$2:$A$201<$A24)*($A24-'OI Data'!$A$2:$A$201)*'OI Data'!$B$2:$B$201)+SUMPRODUCT(('OI Data'!$A$2:$A$201>$A24)*('OI Data'!$A$2:$A$201-$A24)*'OI Data'!$C$2:$C$201)) | C24: =IF($A24="","",IF('OI Data'!B24=0,IF('OI Data'!C24=0,"-","Put ล้วน"),'OI Data'!C24/'OI Data'!B24)) | E24: จำนวนแถวที่คำนวณ | F24: =COUNT('OI Data'!$A$2:$A$201)
A25: =IF('OI Data'!A25="","",'OI Data'!A25) | B25: =IF($A25="","",SUMPRODUCT(('OI Data'!$A$2:$A$201<$A25)*($A25-'OI Data'!$A$2:$A$201)*'OI Data'!$B$2:$B$201)+SUMPRODUCT(('OI Data'!$A$2:$A$201>$A25)*('OI Data'!$A$2:$A$201-$A25)*'OI Data'!$C$2:$C$201)) | C25: =IF($A25="","",IF('OI Data'!B25=0,IF('OI Data'!C25=0,"-","Put ล้วน"),'OI Data'!C25/'OI Data'!B25)) | E25: รวม Call OI ที่กรอก | F25: =SUM('OI Data'!$B$2:$B$201)
A26: =IF('OI Data'!A26="","",'OI Data'!A26) | B26: =IF($A26="","",SUMPRODUCT(('OI Data'!$A$2:$A$201<$A26)*($A26-'OI Data'!$A$2:$A$201)*'OI Data'!$B$2:$B$201)+SUMPRODUCT(('OI Data'!$A$2:$A$201>$A26)*('OI Data'!$A$2:$A$201-$A26)*'OI Data'!$C$2:$C$201)) | C26: =IF($A26="","",IF('OI Data'!B26=0,IF('OI Data'!C26=0,"-","Put ล้วน"),'OI Data'!C26/'OI Data'!B26)) | E26: รวม Put OI ที่กรอก | F26: =SUM('OI Data'!$C$2:$C$201)
A27: =IF('OI Data'!A27="","",'OI Data'!A27) | B27: =IF($A27="","",SUMPRODUCT(('OI Data'!$A$2:$A$201<$A27)*($A27-'OI Data'!$A$2:$A$201)*'OI Data'!$B$2:$B$201)+SUMPRODUCT(('OI Data'!$A$2:$A$201>$A27)*('OI Data'!$A$2:$A$201-$A27)*'OI Data'!$C$2:$C$201)) | C27: =IF($A27="","",IF('OI Data'!B27=0,IF('OI Data'!C27=0,"-","Put ล้วน"),'OI Data'!C27/'OI Data'!B27)) | E27: น้ำหนักขอบ (3 แถวบน+ล่าง) | F27: =IF(OR((F25+F26)=0,F24<6),"",(SUM('OI Data'!$B$2:$C$4)+SUM(OFFSET('OI Data'!$B$2,F24-3,0,3,2)))/(F25+F26))
A28: =IF('OI Data'!A28="","",'OI Data'!A28) | B28: =IF($A28="","",SUMPRODUCT(('OI Data'!$A$2:$A$201<$A28)*($A28-'OI Data'!$A$2:$A$201)*'OI Data'!$B$2:$B$201)+SUMPRODUCT(('OI Data'!$A$2:$A$201>$A28)*('OI Data'!$A$2:$A$201-$A28)*'OI Data'!$C$2:$C$201)) | C28: =IF($A28="","",IF('OI Data'!B28=0,IF('OI Data'!C28=0,"-","Put ล้วน"),'OI Data'!C28/'OI Data'!B28)) | E28: ครอบคลุมเทียบยอด CME | F28: =IF(OR(NOT(ISNUMBER('OI Data'!F5)),NOT(ISNUMBER('OI Data'!F6))),"ยังไม่ได้กรอกยอด CME",(F25+F26)/('OI Data'!F5+'OI Data'!F6))
A29: =IF('OI Data'!A29="","",'OI Data'!A29) | B29: =IF($A29="","",SUMPRODUCT(('OI Data'!$A$2:$A$201<$A29)*($A29-'OI Data'!$A$2:$A$201)*'OI Data'!$B$2:$B$201)+SUMPRODUCT(('OI Data'!$A$2:$A$201>$A29)*('OI Data'!$A$2:$A$201-$A29)*'OI Data'!$C$2:$C$201)) | C29: =IF($A29="","",IF('OI Data'!B29=0,IF('OI Data'!C29=0,"-","Put ล้วน"),'OI Data'!C29/'OI Data'!B29)) | E29: ระดับความมั่นใจของข้อมูล | F29: =IF(ISNUMBER(F28),IF(F28>=0.98,"สูง - ครอบคลุม "&TEXT(F28,"0%")&" ของยอด CME",IF(F28>=0.9,"ปานกลาง - ครอบคลุม "&TEXT(F28,"0%")&" ยังขาดบ้าง","ต่ำ - ครอบคลุมแค่ "&TEXT(F28,"0%")&" ควรกรอกเพิ่ม")),IF(F27="","",IF(F27<=0.01,"ปานกลาง - ขอบเบา แต่ยังไม่ได้ยืนยันกับยอด CME",IF(F27<=0.03,"ปานกลาง - ขอบยังมีน้ำหนัก แนะนำกรอกยอด CME","ต่ำ - ขอบยังหนัก ควรกรอกยอด CME เพื่อวัดจริง"))))
A30: =IF('OI Data'!A30="","",'OI Data'!A30) | B30: =IF($A30="","",SUMPRODUCT(('OI Data'!$A$2:$A$201<$A30)*($A30-'OI Data'!$A$2:$A$201)*'OI Data'!$B$2:$B$201)+SUMPRODUCT(('OI Data'!$A$2:$A$201>$A30)*('OI Data'!$A$2:$A$201-$A30)*'OI Data'!$C$2:$C$201)) | C30: =IF($A30="","",IF('OI Data'!B30=0,IF('OI Data'!C30=0,"-","Put ล้วน"),'OI Data'!C30/'OI Data'!B30)) | E30: แนะนำ | F30: =IF(F4="","กรอกราคาปัจจุบันก่อน", IF('OI Data'!F2="","กรอก Expiration code", IF(NOT(ISNUMBER('OI Data'!F3)),"กรอกวัน settlement ของข้อมูล", IF(NOT(ISNUMBER(F28)),"กรอกยอดรวม CME ที่ OI Data F5-F6", IF(F27>0.03,"ขยายช่วง strike ให้ขอบบางลง", "ข้อมูลครบแล้ว - บันทึกลง log ได้")))))
A31: =IF('OI Data'!A31="","",'OI Data'!A31) | B31: =IF($A31="","",SUMPRODUCT(('OI Data'!$A$2:$A$201<$A31)*($A31-'OI Data'!$A$2:$A$201)*'OI Data'!$B$2:$B$201)+SUMPRODUCT(('OI Data'!$A$2:$A$201>$A31)*('OI Data'!$A$2:$A$201-$A31)*'OI Data'!$C$2:$C$201)) | C31: =IF($A31="","",IF('OI Data'!B31=0,IF('OI Data'!C31=0,"-","Put ล้วน"),'OI Data'!C31/'OI Data'!B31)) | E31: สรุปว่าควรใช้ไหม
A32: =IF('OI Data'!A32="","",'OI Data'!A32) | B32: =IF($A32="","",SUMPRODUCT(('OI Data'!$A$2:$A$201<$A32)*($A32-'OI Data'!$A$2:$A$201)*'OI Data'!$B$2:$B$201)+SUMPRODUCT(('OI Data'!$A$2:$A$201>$A32)*('OI Data'!$A$2:$A$201-$A32)*'OI Data'!$C$2:$C$201)) | C32: =IF($A32="","",IF('OI Data'!B32=0,IF('OI Data'!C32=0,"-","Put ล้วน"),'OI Data'!C32/'OI Data'!B32)) | E32: คำตอบ | F32: =IF(F8="","กรอกราคาปัจจุบันก่อน",IF(ABS(F8)<F9,"ข้ามไป - อยู่โซนกลาง ไม่มี edge",IF(F15>=5,"ระวัง - ก้นหุบแบน ใช้เป็นโซนเท่านั้น",IF(F21="ขัดแย้ง - ตรวจข้อมูลอีกครั้ง","ระวัง - P/C Ratio ขัดแย้งกับทิศทาง",IF(LEFT(F29,3)="ต่ำ","ระวัง - ข้อมูลอาจไม่ครบ ใช้ด้วยความระมัดระวัง","พอใช้เป็นข้อมูลประกอบได้ แต่ต้องมีเหตุผลทิศทางจากที่อื่น")))))
A33: =IF('OI Data'!A33="","",'OI Data'!A33) | B33: =IF($A33="","",SUMPRODUCT(('OI Data'!$A$2:$A$201<$A33)*($A33-'OI Data'!$A$2:$A$201)*'OI Data'!$B$2:$B$201)+SUMPRODUCT(('OI Data'!$A$2:$A$201>$A33)*('OI Data'!$A$2:$A$201-$A33)*'OI Data'!$C$2:$C$201)) | C33: =IF($A33="","",IF('OI Data'!B33=0,IF('OI Data'!C33=0,"-","Put ล้วน"),'OI Data'!C33/'OI Data'!B33)) | E33: เตือนเรื่อง DTE | F33: =IF(NOT(ISNUMBER('OI Data'!F4)),"กรอก DTE ในชีท OI Data ด้วย",IF('OI Data'!F4>7,"เกิน 1 สัปดาห์ - งานวิจัยไม่พบนัยสำคัญในช่วงนี้","อยู่ในสัปดาห์สุดท้าย - ช่วงที่งานวิจัยพบผล"))
A34: =IF('OI Data'!A34="","",'OI Data'!A34) | B34: =IF($A34="","",SUMPRODUCT(('OI Data'!$A$2:$A$201<$A34)*($A34-'OI Data'!$A$2:$A$201)*'OI Data'!$B$2:$B$201)+SUMPRODUCT(('OI Data'!$A$2:$A$201>$A34)*('OI Data'!$A$2:$A$201-$A34)*'OI Data'!$C$2:$C$201)) | C34: =IF($A34="","",IF('OI Data'!B34=0,IF('OI Data'!C34=0,"-","Put ล้วน"),'OI Data'!C34/'OI Data'!B34))
A35: =IF('OI Data'!A35="","",'OI Data'!A35) | B35: =IF($A35="","",SUMPRODUCT(('OI Data'!$A$2:$A$201<$A35)*($A35-'OI Data'!$A$2:$A$201)*'OI Data'!$B$2:$B$201)+SUMPRODUCT(('OI Data'!$A$2:$A$201>$A35)*('OI Data'!$A$2:$A$201-$A35)*'OI Data'!$C$2:$C$201)) | C35: =IF($A35="","",IF('OI Data'!B35=0,IF('OI Data'!C35=0,"-","Put ล้วน"),'OI Data'!C35/'OI Data'!B35))
A36: =IF('OI Data'!A36="","",'OI Data'!A36) | B36: =IF($A36="","",SUMPRODUCT(('OI Data'!$A$2:$A$201<$A36)*($A36-'OI Data'!$A$2:$A$201)*'OI Data'!$B$2:$B$201)+SUMPRODUCT(('OI Data'!$A$2:$A$201>$A36)*('OI Data'!$A$2:$A$201-$A36)*'OI Data'!$C$2:$C$201)) | C36: =IF($A36="","",IF('OI Data'!B36=0,IF('OI Data'!C36=0,"-","Put ล้วน"),'OI Data'!C36/'OI Data'!B36))
A37: =IF('OI Data'!A37="","",'OI Data'!A37) | B37: =IF($A37="","",SUMPRODUCT(('OI Data'!$A$2:$A$201<$A37)*($A37-'OI Data'!$A$2:$A$201)*'OI Data'!$B$2:$B$201)+SUMPRODUCT(('OI Data'!$A$2:$A$201>$A37)*('OI Data'!$A$2:$A$201-$A37)*'OI Data'!$C$2:$C$201)) | C37: =IF($A37="","",IF('OI Data'!B37=0,IF('OI Data'!C37=0,"-","Put ล้วน"),'OI Data'!C37/'OI Data'!B37))
A38: =IF('OI Data'!A38="","",'OI Data'!A38) | B38: =IF($A38="","",SUMPRODUCT(('OI Data'!$A$2:$A$201<$A38)*($A38-'OI Data'!$A$2:$A$201)*'OI Data'!$B$2:$B$201)+SUMPRODUCT(('OI Data'!$A$2:$A$201>$A38)*('OI Data'!$A$2:$A$201-$A38)*'OI Data'!$C$2:$C$201)) | C38: =IF($A38="","",IF('OI Data'!B38=0,IF('OI Data'!C38=0,"-","Put ล้วน"),'OI Data'!C38/'OI Data'!B38))
A39: =IF('OI Data'!A39="","",'OI Data'!A39) | B39: =IF($A39="","",SUMPRODUCT(('OI Data'!$A$2:$A$201<$A39)*($A39-'OI Data'!$A$2:$A$201)*'OI Data'!$B$2:$B$201)+SUMPRODUCT(('OI Data'!$A$2:$A$201>$A39)*('OI Data'!$A$2:$A$201-$A39)*'OI Data'!$C$2:$C$201)) | C39: =IF($A39="","",IF('OI Data'!B39=0,IF('OI Data'!C39=0,"-","Put ล้วน"),'OI Data'!C39/'OI Data'!B39))
A40: =IF('OI Data'!A40="","",'OI Data'!A40) | B40: =IF($A40="","",SUMPRODUCT(('OI Data'!$A$2:$A$201<$A40)*($A40-'OI Data'!$A$2:$A$201)*'OI Data'!$B$2:$B$201)+SUMPRODUCT(('OI Data'!$A$2:$A$201>$A40)*('OI Data'!$A$2:$A$201-$A40)*'OI Data'!$C$2:$C$201)) | C40: =IF($A40="","",IF('OI Data'!B40=0,IF('OI Data'!C40=0,"-","Put ล้วน"),'OI Data'!C40/'OI Data'!B40))
...

Sheet Log
A1: วันที่ข้อมูล | B1: สัญญา | C1: DTE | D1: ราคา | E1: Max Pain | F1: ห่างจากราคา % | G1: ก้นหุบ (จำนวน strike) | H1: P/C Ratio | I1: ครอบคลุม CME % | J1: รายงาน | K1: บันทึกเมื่อ
A2: 46283 | B2: MW1 Week 3 - SEP 2026 (U26) | C2: 3 | D2: 4390.7 | E2: 4370 | F2: -0.0047145102 | G2: 6 | H2: 0.80868762 | I2: 1 | J2: PRELIMINARY | K2: 46286.9
A3: 46283 | B3: AB1 Week 4 - SEP 2026 (U26) | C3: 4 | D3: 4390.7 | E3: 4375 | F3: -0.0035757396 | G3: 2 | H3: 1.2703379 | I3: 1 | J3: PRELIMINARY | K3: 46286.907
A4: 46288 | B4: E21 Week 4 - SEP 2026 (U26) | C4: 2 | D4: 4318.4 | E4: 4355 | F4: 0.0084753612 | G4: 4 | H4: 0.79778157 | I4: 1 | J4: PRELIMINARY | K4: 46289.809 | L4: DEC 26
A5: 46290 | B5: MW1 Week 4 - SEP 2026 (U26) | C5: 3 | D5: 4321.2 | E5: 4330 | F5: 0.0020364714 | G5: 3 | H5: 1.1066434 | I5: 1 | J5: PRELIMINARY | K5: 46292.787 | L5: DEC 26
